Workbook

Sheet المحفظة
A1: 💰 محفظة مزرعة هادي إسحاق
A2: رصيد المحفظة الحالي | F2: ='كشف الحساب'!J100
A4: 📋 جدول حركات المحفظة (دخل وصرف)
A5: التاريخ | B5: المرجع | C5: البيان / الوصف | D5: دخل (KD) | E5: صرف (KD) | F5: رصيد (KD)
A6: 2026-04-09 | B6: Inv-001 | C6: بيع عدد١ اناناس | D6: 5 | F6: 5
A7: 2026-04-22 | B7: 8127 | C7: تاير لعربة الرش | E7: 3 | F7: 2
A8: 2026-04-30 | C8: مدخول شهر ابريل | D8: 40.5 | F8: 42.5
A9: 2026-05-09 | B9: Inv-013 | C9: فل عدد 21 سعر الحبه .0.750 | D9: 15.75 | F9: 58.25
A10: 2026-05-09 | B10: Inv-013A | C10: برازيليا عدد 25 سعر الحبه .500 | D10: 12.5 | F10: 70.75
A11: 2026-05-10 | B11: Inv-016 | C11: ودليه عدد 3 الحبه 0.750 | D11: 2.25 | F11: 73
A12: 2026-05-13 | B12: Inv-017 | C12: فل عدد 10 الحبه 0.750 | D12: 7.5 | F12: 80.5
A13: 2026-05-14 | B13: Inv-18A | C13: ربل 4 حبات الحبه 1.500 | D13: 6 | F13: 86.5
A14: 2026-05-14 | B14: Inv-18 | C14: ودليه 8 حبات الحبه 1 | D14: 8 | F14: 94.5
A15: 2026-05-16 | B15: Inv-19 | C15: فل عدد 2 الحبه 0.750 | D15: 1.5 | F15: 96
A16: 2026-05-16 | B16: Inv-20 | C16: صبار اوليفيرا عدد 3 الحبه 0.750 | D16: 2.25 | F16: 98.25
A17: 2026-05-16 | B17: Inv-21 | C17: دارسينا عدد 1 الحبه 2.500 | D17: 2.5 | F17: 100.75
A18: 2026-05-17 | B18: Inv-22 | C18: فل عدد 30 الحبه 0.750 | D18: 22.5 | F18: 123.25
A19: 2026-05-17 | B19: Inv-23 | C19: برازيليا عدد 16 الحبه 0.500 | D19: 8 | F19: 131.25
A20: 2026-05-18 | B20: Inv-24 | C20: فل عدد10 الحبه 0.750 | D20: 7.5 | F20: 138.75
... A25: 2026-05-18 | B25: Inv-29 | C25: برازيليا عدد 10 الحبه 0.500 | D25: 5 | F25: 159.75
A26: 2026-05-18 | B26: 85164 | C26: مبيد اسيتبلان عدد 1 | E26: 9 | F26: 150.75
A27: 2026-05-19 | B27: Inv-30 | C27: فل عدد 30 الحبه 0.750 | D27: 22.5 | F27: 173.25
A28: 2026-05-20 | B28: Inv-31 | C28: فل عدد30 الحبه 0.750 | D28: 22.5 | F28: 195.75
A29: 2026-05-20 | B29: Inv-32 | C29: برازيليا عدد 50 الحبه0.500 | D29: 25 | F29: 220.75
A30: 2026-05-21 | B30: Inv-33 | C30: برازيليا عدد 75 الحبه 0.500 | D30: 37.5 | F30: 258.25
A31: 2026-05-21 | B31: Inv-34 | C31: دارسينيا احمر عدد1 حبه 2.500 | D31: 2.5 | F31: 260.75
A32: 2026-05-22 | B32: Inv-35 | C32: دارسينا حمراء عدد 6 الحبه 2,500 | D32: 15 | F32: 275.75
A33: 2026-05-22 | B33: Inv-36 | C33: ربل عدد4 الحبه 1.500 | D33: 6 | F33: 281.75
A34: 2026-05-25 | B34: Inv-37 | C34: عطره عدد 10 الحبه 0.750 | D34: 7.5 | F34: 289.25
A35: 2026-05-25 | B35: Inv-38 | C35: ودليه عدد 2 الحبه 1 | D35: 2 | F35: 291.25
A36: 2026-05-25 | B36: Inv-39 | C36: داراسينا حمراء عدد4 الحبه 1 | D36: 4 | F36: 295.25
A37: 2026-05-04 | B37: Inv-40 | C37: other | D37: 9 | F37: 304.25
A38: 2026-05-04 | B38: Inv-41 | C38: other | D38: 9 | F38: 313.25
... A45: 2026-05-16 | B45: Inv-47 | C45: other | D45: 3 | F45: 349.6
A46: 2026-05-13 | C46: جبس لتغطيه المحميه | E46: 2.75 | F46: 346.85
A47: 2026-06-02 | B47: Inv-53 | C47: فل عدد 24 الحبه .750 | D47: 18 | F47: 364.85
A48: 2026-06-02 | B48: Inv-54 | C48: دارسينا خضراء عدد 1 الحبه 2 | D48: 2 | F48: 366.85
A49: 2026-06-02 | B49: Inv-55 | C49: افوبيا عدد 2 الحبه .750 | D49: 1.5 | F49: 368.35
A50: 2026-06-02 | B50: Inv-56 | C50: دارسينا سوداء عدد 3 الحبه 1 | D50: 3 | F50: 371.35
A51: 2026-06-04 | B51: inv-57 | C51: فوزير عدد1 قيمه 1 | D51: 1 | F51: 372.35
...

Sheet كشف الحساب
A1: كشف حساب المزرعة — Farm Account Statement
A2: الرصيد الافتتاحي / Opening Balance | D2: 0 | E2: ← اكتب الرصيد الافتتاحي هنا
A3: التاريخ Date | B3: المرجع Ref # | C3: البيان / الوصف Description | D3: سحب (مدين) Debit | E3: إيداع (دائن) Credit | F3: طريقة الدفع Pay Method | G3: الدافع / من المحفظة Paid By | H3: الحالة Status | I3: بند الصرف Wallet Band | J3: الرصيد Balance | K3: ملاحظات Notes | L3: # إيداع | M3: # محفظة | N3: # طباعة | O3: # شركاء
A4: 46117 | B4: 82869 | C4: مبيدات الاتحاد الكويتي للمزارعين(4.500) | F4: نقداً | G4: المحفظة | H4: تم الدفع | I4: مبيدات وأسمدة | J4: =IFERROR(IF(AND(D4="",E4="",A4="",B4="",C4=""),"", D2+IF(E4="",0,E4)-IF(OR(G4="أبو اسحاق",G4="أبو آدم",G4="أبو اسحاق ",G4="أبو آدم "),0,IF(D4="",0,D4))),D2) | L4: =IF(E4>0,COUNTIF($E$4:E4,">0"),"") | M4: =IF(AND(D4>0,G4="المحفظة"),COUNTIFS($D$4:D4,">"&0,$G$4:G4,"المحفظة"),"") | N4: =IF(AND(OR('طباعة كشف الحساب'!$C$2="الكل",MONTH(A4)=IFERROR(MATCH('طباعة كشف الحساب'!$C$2,{"يناير","فبراير","مارس","أبريل","مايو","يونيو","يوليو","أغسطس","سبتمبر","أكتوبر","نوفمبر","ديسمبر"},0),0)),OR('طباعة كشف الحساب'!$F$2="الكل",YEAR(A4)=IFERROR(VALUE('طباعة كشف الحساب'!$F$2),0)),A4<>""),1,"") | O4: =IF(AND(D4>0,F4="أحد الشركاء"),1,"")
A5: 46121 | B5: Inv-001 | C5: بيع عدد١ اناناس | E5: 5 | F5: نقداً | H5: تم الدفع | J5: =IF(AND(D5="",E5="",A5="",B5="",C5=""),"", IFERROR(IF(J4="",D2,J4),D2)+IF(E5="",0,E5)-IF(OR(G5="أبو اسحاق",G5="أبو آدم",G5="أبو اسحاق ",G5="أبو آدم "),0,IF(D5="",0,D5))) | L5: =IF(E5>0,COUNTIF($E$4:E5,">0"),"") | M5: =IF(AND(D5>0,G5="المحفظة"),COUNTIFS($D$4:D5,">"&0,$G$4:G5,"المحفظة"),"") | N5: =IF(AND(OR('طباعة كشف الحساب'!$C$2="الكل",MONTH(A5)=IFERROR(MATCH('طباعة كشف الحساب'!$C$2,{"يناير","فبراير","مارس","أبريل","مايو","يونيو","يوليو","أغسطس","سبتمبر","أكتوبر","نوفمبر","ديسمبر"},0),0)),OR('طباعة كشف الحساب'!$F$2="الكل",YEAR(A5)=IFERROR(VALUE('طباعة كشف الحساب'!$F$2),0)),A5<>""),IFERROR(MAX($N$4:N4),0)+1,"") | O5: =IF(AND(D5>0,F5="أحد الشركاء"),COUNTIFS($D$4:D5,">"&0,$F$4:F5,"أحد الشركاء"),"")
A6: 46124 | B6: 242 | C6: احواض حجم 18سم عدد 2000-(90) | F6: نقداً | G6: المحفظة | H6: تم الدفع | I6: مستلزمات زراعية | J6: =IF(AND(D6="",E6="",A6="",B6="",C6=""),"", IFERROR(IF(J5="",D2,J5),D2)+IF(E6="",0,E6)-IF(OR(G6="أبو اسحاق",G6="أبو آدم",G6="أبو اسحاق ",G6="أبو آدم "),0,IF(D6="",0,D6))) | L6: =IF(E6>0,COUNTIF($E$4:E6,">0"),"") | M6: =IF(AND(D6>0,G6="المحفظة"),COUNTIFS($D$4:D6,">"&0,$G$4:G6,"المحفظة"),"") | N6: =IF(AND(OR('طباعة كشف الحساب'!$C$2="الكل",MONTH(A6)=IFERROR(MATCH('طباعة كشف الحساب'!$C$2,{"يناير","فبراير","مارس","أبريل","مايو","يونيو","يوليو","أغسطس","سبتمبر","أكتوبر","نوفمبر","ديسمبر"},0),0)),OR('طباعة كشف الحساب'!$F$2="الكل",YEAR(A6)=IFERROR(VALUE('طباعة كشف الحساب'!$F$2),0)),A6<>""),IFERROR(MAX($N$4:N5),0)+1,"") | O6: =IF(AND(D6>0,F6="أحد الشركاء"),COUNTIFS($D$4:D6,">"&0,$F$4:F6,"أحد الشركاء"),"")
A7: 46131 | C7: تبديل كمبرسيور ثلاجة العمال | D7: 45 | F7: أحد الشركاء | G7: أبو اسحاق | H7: معلق | I7: صيانة المعدات | J7: =IF(AND(D7="",E7="",A7="",B7="",C7=""),"", IFERROR(IF(J6="",D2,J6),D2)+IF(E7="",0,E7)-IF(OR(G7="أبو اسحاق",G7="أبو آدم",G7="أبو اسحاق ",G7="أبو آدم "),0,IF(D7="",0,D7))) | L7: =IF(E7>0,COUNTIF($E$4:E7,">0"),"") | M7: =IF(AND(D7>0,G7="المحفظة"),COUNTIFS($D$4:D7,">"&0,$G$4:G7,"المحفظة"),"") | N7: =IF(AND(OR('طباعة كشف الحساب'!$C$2="الكل",MONTH(A7)=IFERROR(MATCH('طباعة كشف الحساب'!$C$2,{"يناير","فبراير","مارس","أبريل","مايو","يونيو","يوليو","أغسطس","سبتمبر","أكتوبر","نوفمبر","ديسمبر"},0),0)),OR('طباعة كشف الحساب'!$F$2="الكل",YEAR(A7)=IFERROR(VALUE('طباعة كشف الحساب'!$F$2),0)),A7<>""),IFERROR(MAX($N$4:N6),0)+1,"") | O7: =IF(AND(D7>0,F7="أحد الشركاء"),COUNTIFS($D$4:D7,">"&0,$F$4:F7,"أحد الشركاء"),"")
A8: 46134 | B8: 11300 | C8: فلاتر كيميكال لمحطة التحلية | D8: 55 | F8: أحد الشركاء | G8: أبو اسحاق | H8: معلق | I8: وقود ومحروقات | J8: =IF(AND(D8="",E8="",A8="",B8="",C8=""),"", IFERROR(IF(J7="",D2,J7),D2)+IF(E8="",0,E8)-IF(OR(G8="أبو اسحاق",G8="أبو آدم",G8="أبو اسحاق ",G8="أبو آدم "),0,IF(D8="",0,D8))) | L8: =IF(E8>0,COUNTIF($E$4:E8,">0"),"") | M8: =IF(AND(D8>0,G8="المحفظة"),COUNTIFS($D$4:D8,">"&0,$G$4:G8,"المحفظة"),"") | N8: =IF(AND(OR('طباعة كشف الحساب'!$C$2="الكل",MONTH(A8)=IFERROR(MATCH('طباعة كشف الحساب'!$C$2,{"يناير","فبراير","مارس","أبريل","مايو","يونيو","يوليو","أغسطس","سبتمبر","أكتوبر","نوفمبر","ديسمبر"},0),0)),OR('طباعة كشف الحساب'!$F$2="الكل",YEAR(A8)=IFERROR(VALUE('طباعة كشف الحساب'!$F$2),0)),A8<>""),IFERROR(MAX($N$4:N7),0)+1,"") | O8: =IF(AND(D8>0,F8="أحد الشركاء"),COUNTIFS($D$4:D8,">"&0,$F$4:F8,"أحد الشركاء"),"")
A9: 46134 | C9: ديزل لمكينة الكهرباء | D9: 20 | F9: أحد الشركاء | G9: أبو اسحاق | H9: معلق | I9: وقود ومحروقات | J9: =IF(AND(D9="",E9="",A9="",B9="",C9=""),"", IFERROR(IF(J8="",D2,J8),D2)+IF(E9="",0,E9)-IF(OR(G9="أبو اسحاق",G9="أبو آدم",G9="أبو اسحاق ",G9="أبو آدم "),0,IF(D9="",0,D9))) | L9: =IF(E9>0,COUNTIF($E$4:E9,">0"),"") | M9: =IF(AND(D9>0,G9="المحفظة"),COUNTIFS($D$4:D9,">"&0,$G$4:G9,"المحفظة"),"") | N9: =IF(AND(OR('طباعة كشف الحساب'!$C$2="الكل",MONTH(A9)=IFERROR(MATCH('طباعة كشف الحساب'!$C$2,{"يناير","فبراير","مارس","أبريل","مايو","يونيو","يوليو","أغسطس","سبتمبر","أكتوبر","نوفمبر","ديسمبر"},0),0)),OR('طباعة كشف الحساب'!$F$2="الكل",YEAR(A9)=IFERROR(VALUE('طباعة كشف الحساب'!$F$2),0)),A9<>""),IFERROR(MAX($N$4:N8),0)+1,"") | O9: =IF(AND(D9>0,F9="أحد الشركاء"),COUNTIFS($D$4:D9,">"&0,$F$4:F9,"أحد الشركاء"),"")
A10: 46134 | B10: 8127 | C10: تاير لعربة الرش | D10: 3 | F10: نقداً | G10: المحفظة | H10: تم الدفع | I10: مستلزمات زراعية | J10: =IF(AND(D10="",E10="",A10="",B10="",C10=""),"", IFERROR(IF(J9="",D2,J9),D2)+IF(E10="",0,E10)-IF(OR(G10="أبو اسحاق",G10="أبو آدم",G10="أبو اسحاق ",G10="أبو آدم "),0,IF(D10="",0,D10))) | K10: تم الصرف | L10: =IF(E10>0,COUNTIF($E$4:E10,">0"),"") | M10: =IF(AND(D10>0,G10="المحفظة"),COUNTIFS($D$4:D10,">"&0,$G$4:G10,"المحفظة"),"") | N10: =IF(AND(OR('طباعة كشف الحساب'!$C$2="الكل",MONTH(A10)=IFERROR(MATCH('طباعة كشف الحساب'!$C$2,{"يناير","فبراير","مارس","أبريل","مايو","يونيو","يوليو","أغسطس","سبتمبر","أكتوبر","نوفمبر","ديسمبر"},0),0)),OR('طباعة كشف الحساب'!$F$2="الكل",YEAR(A10)=IFERROR(VALUE('طباعة كشف الحساب'!$F$2),0)),A10<>""),IFERROR(MAX($N$4:N9),0)+1,"") | O10: =IF(AND(D10>0,F10="أحد الشركاء"),COUNTIFS($D$4:D10,">"&0,$F$4:F10,"أحد الشركاء"),"")
A11: 46134 | B11: 242 | C11: احواض حجم25سم عدد 2000 | D11: 190 | F11: أحد الشركاء | G11: أبو آدم | H11: معلق | I11: أحواض وأدوات | J11: =IF(AND(D11="",E11="",A11="",B11="",C11=""),"", IFERROR(IF(J10="",D2,J10),D2)+IF(E11="",0,E11)-IF(OR(G11="أبو اسحاق",G11="أبو آدم",G11="أبو اسحاق ",G11="أبو آدم "),0,IF(D11="",0,D11))) | L11: =IF(E11>0,COUNTIF($E$4:E11,">0"),"") | M11: =IF(AND(D11>0,G11="المحفظة"),COUNTIFS($D$4:D11,">"&0,$G$4:G11,"المحفظة"),"") | N11: =IF(AND(OR('طباعة كشف الحساب'!$C$2="الكل",MONTH(A11)=IFERROR(MATCH('طباعة كشف الحساب'!$C$2,{"يناير","فبراير","مارس","أبريل","مايو","يونيو","يوليو","أغسطس","سبتمبر","أكتوبر","نوفمبر","ديسمبر"},0),0)),OR('طباعة كشف الحساب'!$F$2="الكل",YEAR(A11)=IFERROR(VALUE('طباعة كشف الحساب'!$F$2),0)),A11<>""),IFERROR(MAX($N$4:N10),0)+1,"") | O11: =IF(AND(D11>0,F11="أحد الشركاء"),COUNTIFS($D$4:D11,">"&0,$F$4:F11,"أحد الشركاء"),"")
A12: 46142 | C12: مدخول شهر ابريل | E12: 40.5 | J12: =IF(AND(D12="",E12="",A12="",B12="",C12=""),"", IFERROR(IF(J11="",D2,J11),D2)+IF(E12="",0,E12)-IF(OR(G12="أبو اسحاق",G12="أبو آدم",G12="أبو اسحاق ",G12="أبو آدم "),0,IF(D12="",0,D12))) | L12: =IF(E12>0,COUNTIF($E$4:E12,">0"),"") | M12: =IF(AND(D12>0,G12="المحفظة"),COUNTIFS($D$4:D12,">"&0,$G$4:G12,"المحفظة"),"") | N12: =IF(AND(OR('طباعة كشف الحساب'!$C$2="الكل",MONTH(A12)=IFERROR(MATCH('طباعة كشف الحساب'!$C$2,{"يناير","فبراير","مارس","أبريل","مايو","يونيو","يوليو","أغسطس","سبتمبر","أكتوبر","نوفمبر","ديسمبر"},0),0)),OR('طباعة كشف الحساب'!$F$2="الكل",YEAR(A12)=IFERROR(VALUE('طباعة كشف الحساب'!$F$2),0)),A12<>""),IFERROR(MAX($N$4:N11),0)+1,"") | O12: =IF(AND(D12>0,F12="أحد الشركاء"),COUNTIFS($D$4:D12,">"&0,$F$4:F12,"أحد الشركاء"),"")
A13: 46142 | B13: 40505 | C13: احواض حجم 14سم عدد 2000(40) | F13: نقداً | G13: المحفظة | H13: تم الدفع | I13: أحواض وأدوات | J13: =IF(AND(D13="",E13="",A13="",B13="",C13=""),"", IFERROR(IF(J12="",D2,J12),D2)+IF(E13="",0,E13)-IF(OR(G13="أبو اسحاق",G13="أبو آدم",G13="أبو اسحاق ",G13="أبو آدم "),0,IF(D13="",0,D13))) | L13: =IF(E13>0,COUNTIF($E$4:E13,">0"),"") | M13: =IF(AND(D13>0,G13="المحفظة"),COUNTIFS($D$4:D13,">"&0,$G$4:G13,"المحفظة"),"") | N13: =IF(AND(OR('طباعة كشف الحساب'!$C$2="الكل",MONTH(A13)=IFERROR(MATCH('طباعة كشف الحساب'!$C$2,{"يناير","فبراير","مارس","أبريل","مايو","يونيو","يوليو","أغسطس","سبتمبر","أكتوبر","نوفمبر","ديسمبر"},0),0)),OR('طباعة كشف الحساب'!$F$2="الكل",YEAR(A13)=IFERROR(VALUE('طباعة كشف الحساب'!$F$2),0)),A13<>""),IFERROR(MAX($N$4:N12),0)+1,"") | O13: =IF(AND(D13>0,F13="أحد الشركاء"),COUNTIFS($D$4:D13,">"&0,$F$4:F13,"أحد الشركاء"),"")
A14: 46142 | B14: 5370 | C14: جبس لتغطيه المحميه(3) | F14: نقداً | G14: المحفظة | H14: تم الدفع | I14: مبيدات وأسمدة | J14: =IF(AND(D14="",E14="",A14="",B14="",C14=""),"", IFERROR(IF(J13="",D2,J13),D2)+IF(E14="",0,E14)-IF(OR(G14="أبو اسحاق",G14="أبو آدم",G14="أبو اسحاق ",G14="أبو آدم "),0,IF(D14="",0,D14))) | L14: =IF(E14>0,COUNTIF($E$4:E14,">0"),"") | M14: =IF(AND(D14>0,G14="المحفظة"),COUNTIFS($D$4:D14,">"&0,$G$4:G14,"المحفظة"),"") | N14: =IF(AND(OR('طباعة كشف الحساب'!$C$2="الكل",MONTH(A14)=IFERROR(MATCH('طباعة كشف الحساب'!$C$2,{"يناير","فبراير","مارس","أبريل","مايو","يونيو","يوليو","أغسطس","سبتمبر","أكتوبر","نوفمبر","ديسمبر"},0),0)),OR('طباعة كشف الحساب'!$F$2="الكل",YEAR(A14)=IFERROR(VALUE('طباعة كشف الحساب'!$F$2),0)),A14<>""),IFERROR(MAX($N$4:N13),0)+1,"") | O14: =IF(AND(D14>0,F14="أحد الشركاء"),COUNTIFS($D$4:D14,">"&0,$F$4:F14,"أحد الشركاء"),"")
A15: 46142 | C15: بونص عمالة أبريل(5) | F15: نقداً | G15: المحفظة | H15: تم الدفع | I15: رواتب وعمالة | J15: =IF(AND(D15="",E15="",A15="",B15="",C15=""),"", IFERROR(IF(J14="",D3,J14),D3)+IF(E15="",0,E15)-IF(OR(G15="أبو اسحاق",G15="أبو آدم",G15="أبو اسحاق ",G15="أبو آدم "),0,IF(D15="",0,D15))) | L15: =IF(E15>0,COUNTIF($E$4:E15,">0"),"") | N15: =IF(AND(OR('طباعة كشف الحساب'!$C$2="الكل",MONTH(A15)=IFERROR(MATCH('طباعة كشف الحساب'!$C$2,{"يناير","فبراير","مارس","أبريل","مايو","يونيو","يوليو","أغسطس","سبتمبر","أكتوبر","نوفمبر","ديسمبر"},0),0)),OR('طباعة كشف الحساب'!$F$2="الكل",YEAR(A15)=IFERROR(VALUE('طباعة كشف الحساب'!$F$2),0)),A15<>""),IFERROR(MAX($N$4:N14),0)+1,"")
A16: 46151 | B16: Inv-013 | C16: فل عدد 21 سعر الحبه .0.750 | E16: 15.75 | F16: نقداً | H16: تم الدفع | J16: =IF(AND(D16="",E16="",A16="",B16="",C16=""),"", IFERROR(IF(J15="",D2,J15),D2)+IF(E16="",0,E16)-IF(OR(G16="أبو اسحاق",G16="أبو آدم",G16="أبو اسحاق ",G16="أبو آدم "),0,IF(D16="",0,D16))) | L16: =IF(E15>0,COUNTIF($E$4:E15,">0"),"") | M16: =IF(AND(D15>0,G15="المحفظة"),COUNTIFS($D$4:D15,">"&0,$G$4:G15,"المحفظة"),"") | N16: =IF(AND(OR('طباعة كشف الحساب'!$C$2="الكل",MONTH(A16)=IFERROR(MATCH('طباعة كشف الحساب'!$C$2,{"يناير","فبراير","مارس","أبريل","مايو","يونيو","يوليو","أغسطس","سبتمبر","أكتوبر","نوفمبر","ديسمبر"},0),0)),OR('طباعة كشف الحساب'!$F$2="الكل",YEAR(A16)=IFERROR(VALUE('طباعة كشف الحساب'!$F$2),0)),A16<>""),IFERROR(MAX($N$4:N15),0)+1,"") | O16: =IF(AND(D15>0,F15="أحد الشركاء"),COUNTIFS($D$4:D15,">"&0,$F$4:F15,"أحد الشركاء"),"")
A17: 46151 | B17: Inv-013A | C17: برازيليا عدد 25 سعر الحبه .500 | E17: 12.5 | F17: نقداً | G17: المحفظة | H17: تم الدفع | J17: =IF(AND(D17="",E17="",A17="",B17="",C17=""),"", IFERROR(IF(J16="",D2,J16),D2)+IF(E17="",0,E17)-IF(OR(G17="أبو اسحاق",G17="أبو آدم",G17="أبو اسحاق ",G17="أبو آدم "),0,IF(D17="",0,D17))) | L17: =IF(E16>0,COUNTIF($E$4:E16,">0"),"") | M17: =IF(AND(D16>0,G16="المحفظة"),COUNTIFS($D$4:D16,">"&0,$G$4:G16,"المحفظة"),"") | N17: =IF(AND(OR('طباعة كشف الحساب'!$C$2="الكل",MONTH(A17)=IFERROR(MATCH('طباعة كشف الحساب'!$C$2,{"يناير","فبراير","مارس","أبريل","مايو","يونيو","يوليو","أغسطس","سبتمبر","أكتوبر","نوفمبر","ديسمبر"},0),0)),OR('طباعة كشف الحساب'!$F$2="الكل",YEAR(A17)=IFERROR(VALUE('طباعة كشف الحساب'!$F$2),0)),A17<>""),IFERROR(MAX($N$4:N16),0)+1,"") | O17: =IF(AND(D16>0,F16="أحد الشركاء"),COUNTIFS($D$4:D16,">"&0,$F$4:F16,"أحد الشركاء"),"")
A18: 46151 | B18: 18213 | C18: شراء دريل | D18: 9 | F18: أحد الشركاء | G18: أبو اسحاق | H18: معلق | I18: مستلزمات زراعية | J18: =IF(AND(D18="",E18="",A18="",B18="",C18=""),"", IFERROR(IF(J17="",D2,J17),D2)+IF(E18="",0,E18)-IF(OR(G18="أبو اسحاق",G18="أبو آدم",G18="أبو اسحاق ",G18="أبو آدم "),0,IF(D18="",0,D18))) | L18: =IF(E17>0,COUNTIF($E$4:E17,">0"),"") | M18: =IF(AND(D17>0,G17="المحفظة"),COUNTIFS($D$4:D17,">"&0,$G$4:G17,"المحفظة"),"") | N18: =IF(AND(OR('طباعة كشف الحساب'!$C$2="الكل",MONTH(A18)=IFERROR(MATCH('طباعة كشف الحساب'!$C$2,{"يناير","فبراير","مارس","أبريل","مايو","يونيو","يوليو","أغسطس","سبتمبر","أكتوبر","نوفمبر","ديسمبر"},0),0)),OR('طباعة كشف الحساب'!$F$2="الكل",YEAR(A18)=IFERROR(VALUE('طباعة كشف الحساب'!$F$2),0)),A18<>""),IFERROR(MAX($N$4:N17),0)+1,"") | O18: =IF(AND(D17>0,F17="أحد الشركاء"),COUNTIFS($D$4:D17,">"&0,$F$4:F17,"أحد الشركاء"),"")
A19: 46152 | B19: Inv-016 | C19: ودليه عدد 3 الحبه 0.750 | E19: 2.25 | F19: نقداً | J19: =IF(AND(D19="",E19="",A19="",B19="",C19=""),"", IFERROR(IF(J18="",D2,J18),D2)+IF(E19="",0,E19)-IF(OR(G19="أبو اسحاق",G19="أبو آدم",G19="أبو اسحاق ",G19="أبو آدم "),0,IF(D19="",0,D19))) | L19: =IF(E18>0,COUNTIF($E$4:E18,">0"),"") | M19: =IF(AND(D18>0,G18="المحفظة"),COUNTIFS($D$4:D18,">"&0,$G$4:G18,"المحفظة"),"") | N19: =IF(AND(OR('طباعة كشف الحساب'!$C$2="الكل",MONTH(A19)=IFERROR(MATCH('طباعة كشف الحساب'!$C$2,{"يناير","فبراير","مارس","أبريل","مايو","يونيو","يوليو","أغسطس","سبتمبر","أكتوبر","نوفمبر","ديسمبر"},0),0)),OR('طباعة كشف الحساب'!$F$2="الكل",YEAR(A19)=IFERROR(VALUE('طباعة كشف الحساب'!$F$2),0)),A19<>""),IFERROR(MAX($N$4:N18),0)+1,"") | O19: =IF(AND(D18>0,F18="أحد الشركاء"),COUNTIFS($D$4:D18,">"&0,$F$4:F18,"أحد الشركاء"),"")
A20: 46155 | B20: Inv-017 | C20: فل عدد 10 الحبه 0.750 | E20: 7.5 | F20: نقداً | J20: =IF(AND(D20="",E20="",A20="",B20="",C20=""),"", IFERROR(IF(J19="",D2,J19),D2)+IF(E20="",0,E20)-IF(OR(G20="أبو اسحاق",G20="أبو آدم",G20="أبو اسحاق ",G20="أبو آدم "),0,IF(D20="",0,D20))) | L20: =IF(E19>0,COUNTIF($E$4:E19,">0"),"") | M20: =IF(AND(D19>0,G19="المحفظة"),COUNTIFS($D$4:D19,">"&0,$G$4:G19,"المحفظة"),"") | N20: =IF(AND(OR('طباعة كشف الحساب'!$C$2="الكل",MONTH(A20)=IFERROR(MATCH('طباعة كشف الحساب'!$C$2,{"يناير","فبراير","مارس","أبريل","مايو","يونيو","يوليو","أغسطس","سبتمبر","أكتوبر","نوفمبر","ديسمبر"},0),0)),OR('طباعة كشف الحساب'!$F$2="الكل",YEAR(A20)=IFERROR(VALUE('طباعة كشف الحساب'!$F$2),0)),A20<>""),IFERROR(MAX($N$4:N19),0)+1,"") | O20: =IF(AND(D19>0,F19="أحد الشركاء"),COUNTIFS($D$4:D19,">"&0,$F$4:F19,"أحد الشركاء"),"")
A21: 46156 | B21: Inv-18A | C21: ربل 4 حبات الحبه 1.500 | E21: 6 | F21: نقداً | J21: =IF(AND(D21="",E21="",A21="",B21="",C21=""),"", IFERROR(IF(J20="",D2,J20),D2)+IF(E21="",0,E21)-IF(OR(G21="أبو اسحاق",G21="أبو آدم",G21="أبو اسحاق ",G21="أبو آدم "),0,IF(D21="",0,D21))) | L21: =IF(E20>0,COUNTIF($E$4:E20,">0"),"") | M21: =IF(AND(D20>0,G20="المحفظة"),COUNTIFS($D$4:D20,">"&0,$G$4:G20,"المحفظة"),"") | N21: =IF(AND(OR('طباعة كشف الحساب'!$C$2="الكل",MONTH(A21)=IFERROR(MATCH('طباعة كشف الحساب'!$C$2,{"يناير","فبراير","مارس","أبريل","مايو","يونيو","يوليو","أغسطس","سبتمبر","أكتوبر","نوفمبر","ديسمبر"},0),0)),OR('طباعة كشف الحساب'!$F$2="الكل",YEAR(A21)=IFERROR(VALUE('طباعة كشف الحساب'!$F$2),0)),A21<>""),IFERROR(MAX($N$4:N20),0)+1,"") | O21: =IF(AND(D20>0,F20="أحد الشركاء"),COUNTIFS($D$4:D20,">"&0,$F$4:F20,"أحد الشركاء"),"")
A22: 46156 | B22: Inv-18 | C22: ودليه 8 حبات الحبه 1 | E22: 8 | F22: نقداً | J22: =IF(AND(D22="",E22="",A22="",B22="",C22=""),"", IFERROR(IF(J21="",D2,J21),D2)+IF(E22="",0,E22)-IF(OR(G22="أبو اسحاق",G22="أبو آدم",G22="أبو اسحاق ",G22="أبو آدم "),0,IF(D22="",0,D22))) | L22: =IF(E21>0,COUNTIF($E$4:E21,">0"),"") | M22: =IF(AND(D21>0,G21="المحفظة"),COUNTIFS($D$4:D21,">"&0,$G$4:G21,"المحفظة"),"") | N22: =IF(AND(OR('طباعة كشف الحساب'!$C$2="الكل",MONTH(A22)=IFERROR(MATCH('طباعة كشف الحساب'!$C$2,{"يناير","فبراير","مارس","أبريل","مايو","يونيو","يوليو","أغسطس","سبتمبر","أكتوبر","نوفمبر","ديسمبر"},0),0)),OR('طباعة كشف الحساب'!$F$2="الكل",YEAR(A22)=IFERROR(VALUE('طباعة كشف الحساب'!$F$2),0)),A22<>""),IFERROR(MAX($N$4:N21),0)+1,"") | O22: =IF(AND(D21>0,F21="أحد الشركاء"),COUNTIFS($D$4:D21,">"&0,$F$4:F21,"أحد الشركاء"),"")
A23: 46158 | B23: Inv-19 | C23: فل عدد 2 الحبه 0.750 | E23: 1.5 | F23: نقداً | J23: =IF(AND(D23="",E23="",A23="",B23="",C23=""),"", IFERROR(IF(J22="",D2,J22),D2)+IF(E23="",0,E23)-IF(OR(G23="أبو اسحاق",G23="أبو آدم",G23="أبو اسحاق ",G23="أبو آدم "),0,IF(D23="",0,D23))) | L23: =IF(E22>0,COUNTIF($E$4:E22,">0"),"") | M23: =IF(AND(D22>0,G22="المحفظة"),COUNTIFS($D$4:D22,">"&0,$G$4:G22,"المحفظة"),"") | N23: =IF(AND(OR('طباعة كشف الحساب'!$C$2="الكل",MONTH(A23)=IFERROR(MATCH('طباعة كشف الحساب'!$C$2,{"يناير","فبراير","مارس","أبريل","مايو","يونيو","يوليو","أغسطس","سبتمبر","أكتوبر","نوفمبر","ديسمبر"},0),0)),OR('طباعة كشف الحساب'!$F$2="الكل",YEAR(A23)=IFERROR(VALUE('طباعة كشف الحساب'!$F$2),0)),A23<>""),IFERROR(MAX($N$4:N22),0)+1,"") | O23: =IF(AND(D22>0,F22="أحد الشركاء"),COUNTIFS($D$4:D22,">"&0,$F$4:F22,"أحد الشركاء"),"")
A24: 46158 | B24: Inv-20 | C24: صبار اوليفيرا عدد 3 الحبه 0.750 | E24: 2.25 | F24: نقداً | J24: =IF(AND(D24="",E24="",A24="",B24="",C24=""),"", IFERROR(IF(J23="",D2,J23),D2)+IF(E24="",0,E24)-IF(OR(G24="أبو اسحاق",G24="أبو آدم",G24="أبو اسحاق ",G24="أبو آدم "),0,IF(D24="",0,D24))) | L24: =IF(E23>0,COUNTIF($E$4:E23,">0"),"") | M24: =IF(AND(D23>0,G23="المحفظة"),COUNTIFS($D$4:D23,">"&0,$G$4:G23,"المحفظة"),"") | N24: =IF(AND(OR('طباعة كشف الحساب'!$C$2="الكل",MONTH(A24)=IFERROR(MATCH('طباعة كشف الحساب'!$C$2,{"يناير","فبراير","مارس","أبريل","مايو","يونيو","يوليو","أغسطس","سبتمبر","أكتوبر","نوفمبر","ديسمبر"},0),0)),OR('طباعة كشف الحساب'!$F$2="الكل",YEAR(A24)=IFERROR(VALUE('طباعة كشف الحساب'!$F$2),0)),A24<>""),IFERROR(MAX($N$4:N23),0)+1,"") | O24: =IF(AND(D23>0,F23="أحد الشركاء"),COUNTIFS($D$4:D23,">"&0,$F$4:F23,"أحد الشركاء"),"")
A25: 46158 | B25: Inv-21 | C25: دارسينا عدد 1 الحبه 2.500 | E25: 2.5 | F25: نقداً | J25: =IF(AND(D25="",E25="",A25="",B25="",C25=""),"", IFERROR(IF(J24="",D2,J24),D2)+IF(E25="",0,E25)-IF(OR(G25="أبو اسحاق",G25="أبو آدم",G25="أبو اسحاق ",G25="أبو آدم "),0,IF(D25="",0,D25))) | L25: =IF(E24>0,COUNTIF($E$4:E24,">0"),"") | M25: =IF(AND(D24>0,G24="المحفظة"),COUNTIFS($D$4:D24,">"&0,$G$4:G24,"المحفظة"),"") | N25: =IF(AND(OR('طباعة كشف الحساب'!$C$2="الكل",MONTH(A25)=IFERROR(MATCH('طباعة كشف الحساب'!$C$2,{"يناير","فبراير","مارس","أبريل","مايو","يونيو","يوليو","أغسطس","سبتمبر","أكتوبر","نوفمبر","ديسمبر"},0),0)),OR('طباعة كشف الحساب'!$F$2="الكل",YEAR(A25)=IFERROR(VALUE('طباعة كشف الحساب'!$F$2),0)),A25<>""),IFERROR(MAX($N$4:N24),0)+1,"") | O25: =IF(AND(D24>0,F24="أحد الشركاء"),COUNTIFS($D$4:D24,">"&0,$F$4:F24,"أحد الشركاء"),"")
A26: 46159 | B26: Inv-22 | C26: فل عدد 30 الحبه 0.750 | E26: 22.5 | F26: نقداً | J26: =IF(AND(D26="",E26="",A26="",B26="",C26=""),"", IFERROR(IF(J25="",D2,J25),D2)+IF(E26="",0,E26)-IF(OR(G26="أبو اسحاق",G26="أبو آدم",G26="أبو اسحاق ",G26="أبو آدم "),0,IF(D26="",0,D26))) | K26: تم إعطاء 1 حبه هديه الإجمالي 31 حبه | L26: =IF(E25>0,COUNTIF($E$4:E25,">0"),"") | M26: =IF(AND(D25>0,G25="المحفظة"),COUNTIFS($D$4:D25,">"&0,$G$4:G25,"المحفظة"),"") | N26: =IF(AND(OR('طباعة كشف الحساب'!$C$2="الكل",MONTH(A26)=IFERROR(MATCH('طباعة كشف الحساب'!$C$2,{"يناير","فبراير","مارس","أبريل","مايو","يونيو","يوليو","أغسطس","سبتمبر","أكتوبر","نوفمبر","ديسمبر"},0),0)),OR('طباعة كشف الحساب'!$F$2="الكل",YEAR(A26)=IFERROR(VALUE('طباعة كشف الحساب'!$F$2),0)),A26<>""),IFERROR(MAX($N$4:N25),0)+1,"") | O26: =IF(AND(D25>0,F25="أحد الشركاء"),COUNTIFS($D$4:D25,">"&0,$F$4:F25,"أحد الشركاء"),"")
A27: 46159 | B27: Inv-23 | C27: برازيليا عدد 16 الحبه 0.500 | E27: 8 | F27: نقداً | J27: =IF(AND(D27="",E27="",A27="",B27="",C27=""),"", IFERROR(IF(J26="",D2,J26),D2)+IF(E27="",0,E27)-IF(OR(G27="أبو اسحاق",G27="أبو آدم",G27="أبو اسحاق ",G27="أبو آدم "),0,IF(D27="",0,D27))) | L27: =IF(E26>0,COUNTIF($E$4:E26,">0"),"") | M27: =IF(AND(D26>0,G26="المحفظة"),COUNTIFS($D$4:D26,">"&0,$G$4:G26,"المحفظة"),"") | N27: =IF(AND(OR('طباعة كشف الحساب'!$C$2="الكل",MONTH(A27)=IFERROR(MATCH('طباعة كشف الحساب'!$C$2,{"يناير","فبراير","مارس","أبريل","مايو","يونيو","يوليو","أغسطس","سبتمبر","أكتوبر","نوفمبر","ديسمبر"},0),0)),OR('طباعة كشف الحساب'!$F$2="الكل",YEAR(A27)=IFERROR(VALUE('طباعة كشف الحساب'!$F$2),0)),A27<>""),IFERROR(MAX($N$4:N26),0)+1,"") | O27: =IF(AND(D26>0,F26="أحد الشركاء"),COUNTIFS($D$4:D26,">"&0,$F$4:F26,"أحد الشركاء"),"")
A28: 46160 | B28: Inv-24 | C28: فل عدد10 الحبه 0.750 | E28: 7.5 | F28: نقداً | J28: =IF(AND(D28="",E28="",A28="",B28="",C28=""),"", IFERROR(IF(J27="",D2,J27),D2)+IF(E28="",0,E28)-IF(OR(G28="أبو اسحاق",G28="أبو آدم",G28="أبو اسحاق ",G28="أبو آدم "),0,IF(D28="",0,D28))) | L28: =IF(E27>0,COUNTIF($E$4:E27,">0"),"") | M28: =IF(AND(D27>0,G27="المحفظة"),COUNTIFS($D$4:D27,">"&0,$G$4:G27,"المحفظة"),"") | N28: =IF(AND(OR('طباعة كشف الحساب'!$C$2="الكل",MONTH(A28)=IFERROR(MATCH('طباعة كشف الحساب'!$C$2,{"يناير","فبراير","مارس","أبريل","مايو","يونيو","يوليو","أغسطس","سبتمبر","أكتوبر","نوفمبر","ديسمبر"},0),0)),OR('طباعة كشف الحساب'!$F$2="الكل",YEAR(A28)=IFERROR(VALUE('طباعة كشف الحساب'!$F$2),0)),A28<>""),IFERROR(MAX($N$4:N27),0)+1,"") | O28: =IF(AND(D27>0,F27="أحد الشركاء"),COUNTIFS($D$4:D27,">"&0,$F$4:F27,"أحد الشركاء"),"")
A29: 46160 | B29: Inv-25 | C29: دارسيناحمراء عدد 1 | E29: 5 | F29: نقداً | J29: =IF(AND(D29="",E29="",A29="",B29="",C29=""),"", IFERROR(IF(J28="",D2,J28),D2)+IF(E29="",0,E29)-IF(OR(G29="أبو اسحاق",G29="أبو آدم",G29="أبو اسحاق ",G29="أبو آدم "),0,IF(D29="",0,D29))) | L29: =IF(E28>0,COUNTIF($E$4:E28,">0"),"") | M29: =IF(AND(D28>0,G28="المحفظة"),COUNTIFS($D$4:D28,">"&0,$G$4:G28,"المحفظة"),"") | N29: =IF(AND(OR('طباعة كشف الحساب'!$C$2="الكل",MONTH(A29)=IFERROR(MATCH('طباعة كشف الحساب'!$C$2,{"يناير","فبراير","مارس","أبريل","مايو","يونيو","يوليو","أغسطس","سبتمبر","أكتوبر","نوفمبر","ديسمبر"},0),0)),OR('طباعة كشف الحساب'!$F$2="الكل",YEAR(A29)=IFERROR(VALUE('طباعة كشف الحساب'!$F$2),0)),A29<>""),IFERROR(MAX($N$4:N28),0)+1,"") | O29: =IF(AND(D28>0,F28="أحد الشركاء"),COUNTIFS($D$4:D28,">"&0,$F$4:F28,"أحد الشركاء"),"")
A30: 46160 | B30: Inv-26 | C30: دارسينا خضراء عدد 2 الحبه 1.500 | E30: 3 | F30: نقداً | J30: =IF(AND(D30="",E30="",A30="",B30="",C30=""),"", IFERROR(IF(J29="",D2,J29),D2)+IF(E30="",0,E30)-IF(OR(G30="أبو اسحاق",G30="أبو آدم",G30="أبو اسحاق ",G30="أبو آدم "),0,IF(D30="",0,D30))) | L30: =IF(E29>0,COUNTIF($E$4:E29,">0"),"") | M30: =IF(AND(D29>0,G29="المحفظة"),COUNTIFS($D$4:D29,">"&0,$G$4:G29,"المحفظة"),"") | N30: =IF(AND(OR('طباعة كشف الحساب'!$C$2="الكل",MONTH(A30)=IFERROR(MATCH('طباعة كشف الحساب'!$C$2,{"يناير","فبراير","مارس","أبريل","مايو","يونيو","يوليو","أغسطس","سبتمبر","أكتوبر","نوفمبر","ديسمبر"},0),0)),OR('طباعة كشف الحساب'!$F$2="الكل",YEAR(A30)=IFERROR(VALUE('طباعة كشف الحساب'!$F$2),0)),A30<>""),IFERROR(MAX($N$4:N29),0)+1,"") | O30: =IF(AND(D29>0,F29="أحد الشركاء"),COUNTIFS($D$4:D29,">"&0,$F$4:F29,"أحد الشركاء"),"")
A31: 46160 | B31: Inv-27 | C31: ربل عدد 2 الحبه 1.500 | E31: 3 | F31: نقداً | J31: =IF(AND(D31="",E31="",A31="",B31="",C31=""),"", IFERROR(IF(J30="",D2,J30),D2)+IF(E31="",0,E31)-IF(OR(G31="أبو اسحاق",G31="أبو آدم",G31="أبو اسحاق ",G31="أبو آدم "),0,IF(D31="",0,D31))) | L31: =IF(E30>0,COUNTIF($E$4:E30,">0"),"") | M31: =IF(AND(D30>0,G30="المحفظة"),COUNTIFS($D$4:D30,">"&0,$G$4:G30,"المحفظة"),"") | N31: =IF(AND(OR('طباعة كشف الحساب'!$C$2="الكل",MONTH(A31)=IFERROR(MATCH('طباعة كشف الحساب'!$C$2,{"يناير","فبراير","مارس","أبريل","مايو","يونيو","يوليو","أغسطس","سبتمبر","أكتوبر","نوفمبر","ديسمبر"},0),0)),OR('طباعة كشف الحساب'!$F$2="الكل",YEAR(A31)=IFERROR(VALUE('طباعة كشف الحساب'!$F$2),0)),A31<>""),IFERROR(MAX($N$4:N30),0)+1,"") | O31: =IF(AND(D30>0,F30="أحد الشركاء"),COUNTIFS($D$4:D30,">"&0,$F$4:F30,"أحد الشركاء"),"")
A32: 46160 | B32: Inv-28 | C32: دارسينا حمراء عدد2 الحبه 2.500 | E32: 5 | F32: نقداً | J32: =IF(AND(D32="",E32="",A32="",B32="",C32=""),"", IFERROR(IF(J31="",D2,J31),D2)+IF(E32="",0,E32)-IF(OR(G32="أبو اسحاق",G32="أبو آدم",G32="أبو اسحاق ",G32="أبو آدم "),0,IF(D32="",0,D32))) | L32: =IF(E31>0,COUNTIF($E$4:E31,">0"),"") | M32: =IF(AND(D31>0,G31="المحفظة"),COUNTIFS($D$4:D31,">"&0,$G$4:G31,"المحفظة"),"") | N32: =IF(AND(OR('طباعة كشف الحساب'!$C$2="الكل",MONTH(A32)=IFERROR(MATCH('طباعة كشف الحساب'!$C$2,{"يناير","فبراير","مارس","أبريل","مايو","يونيو","يوليو","أغسطس","سبتمبر","أكتوبر","نوفمبر","ديسمبر"},0),0)),OR('طباعة كشف الحساب'!$F$2="الكل",YEAR(A32)=IFERROR(VALUE('طباعة كشف الحساب'!$F$2),0)),A32<>""),IFERROR(MAX($N$4:N31),0)+1,"") | O32: =IF(AND(D31>0,F31="أحد الشركاء"),COUNTIFS($D$4:D31,">"&0,$F$4:F31,"أحد الشركاء"),"")
A33: 46160 | B33: Inv-29 | C33: برازيليا عدد 10 الحبه 0.500 | E33: 5 | F33: نقداً | J33: =IF(AND(D33="",E33="",A33="",B33="",C33=""),"", IFERROR(IF(J32="",D2,J32),D2)+IF(E33="",0,E33)-IF(OR(G33="أبو اسحاق",G33="أبو آدم",G33="أبو اسحاق ",G33="أبو آدم "),0,IF(D33="",0,D33))) | L33: =IF(E32>0,COUNTIF($E$4:E32,">0"),"") | M33: =IF(AND(D32>0,G32="المحفظة"),COUNTIFS($D$4:D32,">"&0,$G$4:G32,"المحفظة"),"") | N33: =IF(AND(OR('طباعة كشف الحساب'!$C$2="الكل",MONTH(A33)=IFERROR(MATCH('طباعة كشف الحساب'!$C$2,{"يناير","فبراير","مارس","أبريل","مايو","يونيو","يوليو","أغسطس","سبتمبر","أكتوبر","نوفمبر","ديسمبر"},0),0)),OR('طباعة كشف الحساب'!$F$2="الكل",YEAR(A33)=IFERROR(VALUE('طباعة كشف الحساب'!$F$2),0)),A33<>""),IFERROR(MAX($N$4:N32),0)+1,"") | O33: =IF(AND(D32>0,F32="أحد الشركاء"),COUNTIFS($D$4:D32,">"&0,$F$4:F32,"أحد الشركاء"),"")
A34: 46160 | B34: 85164 | C34: مبيد اسيتبلان عدد 1 | D34: 9 | F34: نقداً | G34: المحفظة | H34: تم الدفع | I34: مبيدات وأسمدة | J34: =IF(AND(D34="",E34="",A34="",B34="",C34=""),"", IFERROR(IF(J33="",D2,J33),D2)+IF(E34="",0,E34)-IF(OR(G34="أبو اسحاق",G34="أبو آدم",G34="أبو اسحاق ",G34="أبو آدم "),0,IF(D34="",0,D34))) | L34: =IF(E33>0,COUNTIF($E$4:E33,">0"),"") | M34: =IF(AND(D33>0,G33="المحفظة"),COUNTIFS($D$4:D33,">"&0,$G$4:G33,"المحفظة"),"") | N34: =IF(AND(OR('طباعة كشف الحساب'!$C$2="الكل",MONTH(A34)=IFERROR(MATCH('طباعة كشف الحساب'!$C$2,{"يناير","فبراير","مارس","أبريل","مايو","يونيو","يوليو","أغسطس","سبتمبر","أكتوبر","نوفمبر","ديسمبر"},0),0)),OR('طباعة كشف الحساب'!$F$2="الكل",YEAR(A34)=IFERROR(VALUE('طباعة كشف الحساب'!$F$2),0)),A34<>""),IFERROR(MAX($N$4:N33),0)+1,"") | O34: =IF(AND(D33>0,F33="أحد الشركاء"),COUNTIFS($D$4:D33,">"&0,$F$4:F33,"أحد الشركاء"),"")
A35: 46161 | B35: Inv-30 | C35: فل عدد 30 الحبه 0.750 | E35: 22.5 | F35: نقداً | J35: =IF(AND(D35="",E35="",A35="",B35="",C35=""),"", IFERROR(IF(J34="",D2,J34),D2)+IF(E35="",0,E35)-IF(OR(G35="أبو اسحاق",G35="أبو آدم",G35="أبو اسحاق ",G35="أبو آدم "),0,IF(D35="",0,D35))) | L35: =IF(E34>0,COUNTIF($E$4:E34,">0"),"") | M35: =IF(AND(D34>0,G34="المحفظة"),COUNTIFS($D$4:D34,">"&0,$G$4:G34,"المحفظة"),"") | N35: =IF(AND(OR('طباعة كشف الحساب'!$C$2="الكل",MONTH(A35)=IFERROR(MATCH('طباعة كشف الحساب'!$C$2,{"يناير","فبراير","مارس","أبريل","مايو","يونيو","يوليو","أغسطس","سبتمبر","أكتوبر","نوفمبر","ديسمبر"},0),0)),OR('طباعة كشف الحساب'!$F$2="الكل",YEAR(A35)=IFERROR(VALUE('طباعة كشف الحساب'!$F$2),0)),A35<>""),IFERROR(MAX($N$4:N34),0)+1,"") | O35: =IF(AND(D34>0,F34="أحد الشركاء"),COUNTIFS($D$4:D34,">"&0,$F$4:F34,"أحد الشركاء"),"")
A36: 46162 | B36: Inv-31 | C36: فل عدد30 الحبه 0.750 | E36: 22.5 | F36: نقداً | J36: =IF(AND(D36="",E36="",A36="",B36="",C36=""),"", IFERROR(IF(J35="",D2,J35),D2)+IF(E36="",0,E36)-IF(OR(G36="أبو اسحاق",G36="أبو آدم",G36="أبو اسحاق ",G36="أبو آدم "),0,IF(D36="",0,D36))) | L36: =IF(E35>0,COUNTIF($E$4:E35,">0"),"") | M36: =IF(AND(D35>0,G35="المحفظة"),COUNTIFS($D$4:D35,">"&0,$G$4:G35,"المحفظة"),"") | N36: =IF(AND(OR('طباعة كشف الحساب'!$C$2="الكل",MONTH(A36)=IFERROR(MATCH('طباعة كشف الحساب'!$C$2,{"يناير","فبراير","مارس","أبريل","مايو","يونيو","يوليو","أغسطس","سبتمبر","أكتوبر","نوفمبر","ديسمبر"},0),0)),OR('طباعة كشف الحساب'!$F$2="الكل",YEAR(A36)=IFERROR(VALUE('طباعة كشف الحساب'!$F$2),0)),A36<>""),IFERROR(MAX($N$4:N35),0)+1,"") | O36: =IF(AND(D35>0,F35="أحد الشركاء"),COUNTIFS($D$4:D35,">"&0,$F$4:F35,"أحد الشركاء"),"")
A37: 46162 | B37: Inv-32 | C37: برازيليا عدد 50 الحبه0.500 | E37: 25 | F37: نقداً | J37: =IF(AND(D37="",E37="",A37="",B37="",C37=""),"", IFERROR(IF(J36="",D2,J36),D2)+IF(E37="",0,E37)-IF(OR(G37="أبو اسحاق",G37="أبو آدم",G37="أبو اسحاق ",G37="أبو آدم "),0,IF(D37="",0,D37))) | L37: =IF(E36>0,COUNTIF($E$4:E36,">0"),"") | M37: =IF(AND(D36>0,G36="المحفظة"),COUNTIFS($D$4:D36,">"&0,$G$4:G36,"المحفظة"),"") | N37: =IF(AND(OR('طباعة كشف الحساب'!$C$2="الكل",MONTH(A37)=IFERROR(MATCH('طباعة كشف الحساب'!$C$2,{"يناير","فبراير","مارس","أبريل","مايو","يونيو","يوليو","أغسطس","سبتمبر","أكتوبر","نوفمبر","ديسمبر"},0),0)),OR('طباعة كشف الحساب'!$F$2="الكل",YEAR(A37)=IFERROR(VALUE('طباعة كشف الحساب'!$F$2),0)),A37<>""),IFERROR(MAX($N$4:N36),0)+1,"") | O37: =IF(AND(D36>0,F36="أحد الشركاء"),COUNTIFS($D$4:D36,">"&0,$F$4:F36,"أحد الشركاء"),"")
A38: 46163 | B38: Inv-33 | C38: برازيليا عدد 75 الحبه 0.500 | E38: 37.5 | F38: نقداً | J38: =IF(AND(D38="",E38="",A38="",B38="",C38=""),"", IFERROR(IF(J37="",D2,J37),D2)+IF(E38="",0,E38)-IF(OR(G38="أبو اسحاق",G38="أبو آدم",G38="أبو اسحاق ",G38="أبو آدم "),0,IF(D38="",0,D38))) | L38: =IF(E37>0,COUNTIF($E$4:E37,">0"),"") | M38: =IF(AND(D37>0,G37="المحفظة"),COUNTIFS($D$4:D37,">"&0,$G$4:G37,"المحفظة"),"") | N38: =IF(AND(OR('طباعة كشف الحساب'!$C$2="الكل",MONTH(A38)=IFERROR(MATCH('طباعة كشف الحساب'!$C$2,{"يناير","فبراير","مارس","أبريل","مايو","يونيو","يوليو","أغسطس","سبتمبر","أكتوبر","نوفمبر","ديسمبر"},0),0)),OR('طباعة كشف الحساب'!$F$2="الكل",YEAR(A38)=IFERROR(VALUE('طباعة كشف الحساب'!$F$2),0)),A38<>""),IFERROR(MAX($N$4:N37),0)+1,"") | O38: =IF(AND(D37>0,F37="أحد الشركاء"),COUNTIFS($D$4:D37,">"&0,$F$4:F37,"أحد الشركاء"),"")
A39: 46163 | B39: Inv-34 | C39: دارسينيا احمر عدد1 حبه 2.500 | E39: 2.5 | F39: نقداً | J39: =IF(AND(D39="",E39="",A39="",B39="",C39=""),"", IFERROR(IF(J38="",D2,J38),D2)+IF(E39="",0,E39)-IF(OR(G39="أبو اسحاق",G39="أبو آدم",G39="أبو اسحاق ",G39="أبو آدم "),0,IF(D39="",0,D39))) | L39: =IF(E38>0,COUNTIF($E$4:E38,">0"),"") | M39: =IF(AND(D38>0,G38="المحفظة"),COUNTIFS($D$4:D38,">"&0,$G$4:G38,"المحفظة"),"") | N39: =IF(AND(OR('طباعة كشف الحساب'!$C$2="الكل",MONTH(A39)=IFERROR(MATCH('طباعة كشف الحساب'!$C$2,{"يناير","فبراير","مارس","أبريل","مايو","يونيو","يوليو","أغسطس","سبتمبر","أكتوبر","نوفمبر","ديسمبر"},0),0)),OR('طباعة كشف الحساب'!$F$2="الكل",YEAR(A39)=IFERROR(VALUE('طباعة كشف الحساب'!$F$2),0)),A39<>""),IFERROR(MAX($N$4:N38),0)+1,"") | O39: =IF(AND(D38>0,F38="أحد الشركاء"),COUNTIFS($D$4:D38,">"&0,$F$4:F38,"أحد الشركاء"),"")
A40: 46164 | B40: Inv-35 | C40: دارسينا حمراء عدد 6 الحبه 2,500 | E40: 15 | F40: نقداً | J40: =IF(AND(D40="",E40="",A40="",B40="",C40=""),"", IFERROR(IF(J39="",D2,J39),D2)+IF(E40="",0,E40)-IF(OR(G40="أبو اسحاق",G40="أبو آدم",G40="أبو اسحاق ",G40="أبو آدم "),0,IF(D40="",0,D40))) | L40: =IF(E39>0,COUNTIF($E$4:E39,">0"),"") | M40: =IF(AND(D39>0,G39="المحفظة"),COUNTIFS($D$4:D39,">"&0,$G$4:G39,"المحفظة"),"") | N40: =IF(AND(OR('طباعة كشف الحساب'!$C$2="الكل",MONTH(A40)=IFERROR(MATCH('طباعة كشف الحساب'!$C$2,{"يناير","فبراير","مارس","أبريل","مايو","يونيو","يوليو","أغسطس","سبتمبر","أكتوبر","نوفمبر","ديسمبر"},0),0)),OR('طباعة كشف الحساب'!$F$2="الكل",YEAR(A40)=IFERROR(VALUE('طباعة كشف الحساب'!$F$2),0)),A40<>""),IFERROR(MAX($N$4:N39),0)+1,"") | O40: =IF(AND(D39>0,F39="أحد الشركاء"),COUNTIFS($D$4:D39,">"&0,$F$4:F39,"أحد الشركاء"),"")
...

Sheet بنود المحفظة
A1: بنود التسديد من المحفظة
A2: بند الصرف | B2: الوصف | C2: ملاحظات
A3: رواتب العمال
A4: وقود ومحروقات
A5: صيانة المعدات
A6: مستلزمات زراعية
A7: مياه وكهرباء
A8: نقليات وتوصيل
A9: أحواض وأدوات
A10: مبيدات وأسمدة
A11: إيجارات
A12: مصاريف إدارية
A13: مدفوعات المهندس مختار
A14: مدفوعات محمد أبو آدم
... A20: أخرى

Sheet تعليمات
A1: 📘 تعليمات الاستخدام
A2: كشف الحساب — الدفع العادي
A3: ① | B3: اكتب المبلغ في عمود D (سحب) واختر طريقة الدفع = نقداً أو أون لاين أو أحد الشركاء
A4: ② | B4: اختر الدافع G: أبو اسحاق / أبو آدم / نزمول — لا يخصم من المحفظة
A5: كشف الحساب — الدفع من المحفظة
A6: ① | B6: اكتب المبلغ في عمود D (سحب)
A7: ② | B7: عمود F (طريقة الدفع): اختر "من المحفظة"
A8: ③ | B8: عمود G (الدافع): اختر "المحفظة" ← هذا هو المفتاح للخصم التلقائي
A9: ④ | B9: عمود I (بند الصرف): اختر البند المناسب مثل رواتب / وقود / إلخ
A10: ⑤ | B10: 🔄 المبلغ يُخصم تلقائياً من المحفظة — لا تحتاج كتابة أي شيء في ورقة المحفظة
A11: المحفظة — كيف تعمل
A12: ① | B12: القسم الأخضر: جميع الإيرادات (عمود إيداع E في كشف الحساب) تظهر تلقائياً
A13: ② | B13: القسم الأحمر: جميع المصروفات المدفوعة من المحفظة (عند اختيار المحفظة كدافع) تظهر تلقائياً
A14: ③ | B14: رصيد المحفظة = الافتتاحي + إجمالي الإيرادات − إجمالي المصروفات
A15: ④ | B15: الرصيد في الخلية C3 يتحدث فورياً مع أي تغيير في كشف الحساب

Sheet طباعة كشف الحساب
A1: كشف حساب المزرعة — Farm Account Statement
C2: يونيو | D2: 2026 | F2: الكل | G2: ⬆ اختر الشهر والسنة ثم Ctrl+P أو File → Export → PDF
A3: الرصيد الافتتاحي: | D3: ='كشف الحساب'!$D$2
A4: التاريخ | B4: المرجع | C4: البيان / الوصف | D4: سحب | E4: إيداع | F4: طريقة الدفع | G4: الدافع | H4: الحالة | I4: بند الصرف | J4: الرصيد | K4: ملاحظات
A5: =IFERROR(IF(IFERROR(MATCH(1,'كشف الحساب'!$N$4:$N$203,0),0)=0,"",INDEX('كشف الحساب'!$A$4:$A$203,IFERROR(MATCH(1,'كشف الحساب'!$N$4:$N$203,0),0))),"") | B5: =IFERROR(IF(IFERROR(MATCH(1,'كشف الحساب'!$N$4:$N$203,0),0)=0,"",INDEX('كشف الحساب'!$B$4:$B$203,IFERROR(MATCH(1,'كشف الحساب'!$N$4:$N$203,0),0))),"") | C5: =IFERROR(IF(IFERROR(MATCH(1,'كشف الحساب'!$N$4:$N$203,0),0)=0,"",INDEX('كشف الحساب'!$C$4:$C$203,IFERROR(MATCH(1,'كشف الحساب'!$N$4:$N$203,0),0))),"") | D5: =IFERROR(IF(IFERROR(MATCH(1,'كشف الحساب'!$N$4:$N$203,0),0)=0,"",INDEX('كشف الحساب'!$D$4:$D$203,IFERROR(MATCH(1,'كشف الحساب'!$N$4:$N$203,0),0))),"") | E5: =IFERROR(IF(IFERROR(MATCH(1,'كشف الحساب'!$N$4:$N$203,0),0)=0,"",INDEX('كشف الحساب'!$E$4:$E$203,IFERROR(MATCH(1,'كشف الحساب'!$N$4:$N$203,0),0))),"") | F5: =IFERROR(IF(IFERROR(MATCH(1,'كشف الحساب'!$N$4:$N$203,0),0)=0,"",INDEX('كشف الحساب'!$F$4:$F$203,IFERROR(MATCH(1,'كشف الحساب'!$N$4:$N$203,0),0))),"") | G5: =IFERROR(IF(IFERROR(MATCH(1,'كشف الحساب'!$N$4:$N$203,0),0)=0,"",INDEX('كشف الحساب'!$G$4:$G$203,IFERROR(MATCH(1,'كشف الحساب'!$N$4:$N$203,0),0))),"") | H5: =IFERROR(IF(IFERROR(MATCH(1,'كشف الحساب'!$N$4:$N$203,0),0)=0,"",INDEX('كشف الحساب'!$H$4:$H$203,IFERROR(MATCH(1,'كشف الحساب'!$N$4:$N$203,0),0))),"") | I5: =IFERROR(IF(IFERROR(MATCH(1,'كشف الحساب'!$N$4:$N$203,0),0)=0,"",INDEX('كشف الحساب'!$I$4:$I$203,IFERROR(MATCH(1,'كشف الحساب'!$N$4:$N$203,0),0))),"") | J5: =IFERROR(IF(IFERROR(MATCH(1,'كشف الحساب'!$N$4:$N$203,0),0)=0,"",INDEX('كشف الحساب'!$J$4:$J$203,IFERROR(MATCH(1,'كشف الحساب'!$N$4:$N$203,0),0))),"") | K5: =IFERROR(IF(IFERROR(MATCH(1,'كشف الحساب'!$N$4:$N$203,0),0)=0,"",INDEX('كشف الحساب'!$K$4:$K$203,IFERROR(MATCH(1,'كشف الحساب'!$N$4:$N$203,0),0))),"")
A6: =IFERROR(IF(IFERROR(MATCH(2,'كشف الحساب'!$N$4:$N$203,0),0)=0,"",INDEX('كشف الحساب'!$A$4:$A$203,IFERROR(MATCH(2,'كشف الحساب'!$N$4:$N$203,0),0))),"") | B6: =IFERROR(IF(IFERROR(MATCH(2,'كشف الحساب'!$N$4:$N$203,0),0)=0,"",INDEX('كشف الحساب'!$B$4:$B$203,IFERROR(MATCH(2,'كشف الحساب'!$N$4:$N$203,0),0))),"") | C6: =IFERROR(IF(IFERROR(MATCH(2,'كشف الحساب'!$N$4:$N$203,0),0)=0,"",INDEX('كشف الحساب'!$C$4:$C$203,IFERROR(MATCH(2,'كشف الحساب'!$N$4:$N$203,0),0))),"") | D6: =IFERROR(IF(IFERROR(MATCH(2,'كشف الحساب'!$N$4:$N$203,0),0)=0,"",INDEX('كشف الحساب'!$D$4:$D$203,IFERROR(MATCH(2,'كشف الحساب'!$N$4:$N$203,0),0))),"") | E6: =IFERROR(IF(IFERROR(MATCH(2,'كشف الحساب'!$N$4:$N$203,0),0)=0,"",INDEX('كشف الحساب'!$E$4:$E$203,IFERROR(MATCH(2,'كشف الحساب'!$N$4:$N$203,0),0))),"") | F6: =IFERROR(IF(IFERROR(MATCH(2,'كشف الحساب'!$N$4:$N$203,0),0)=0,"",INDEX('كشف الحساب'!$F$4:$F$203,IFERROR(MATCH(2,'كشف الحساب'!$N$4:$N$203,0),0))),"") | G6: =IFERROR(IF(IFERROR(MATCH(2,'كشف الحساب'!$N$4:$N$203,0),0)=0,"",INDEX('كشف الحساب'!$G$4:$G$203,IFERROR(MATCH(2,'كشف الحساب'!$N$4:$N$203,0),0))),"") | H6: =IFERROR(IF(IFERROR(MATCH(2,'كشف الحساب'!$N$4:$N$203,0),0)=0,"",INDEX('كشف الحساب'!$H$4:$H$203,IFERROR(MATCH(2,'كشف الحساب'!$N$4:$N$203,0),0))),"") | I6: =IFERROR(IF(IFERROR(MATCH(2,'كشف الحساب'!$N$4:$N$203,0),0)=0,"",INDEX('كشف الحساب'!$I$4:$I$203,IFERROR(MATCH(2,'كشف الحساب'!$N$4:$N$203,0),0))),"") | J6: =IFERROR(IF(IFERROR(MATCH(2,'كشف الحساب'!$N$4:$N$203,0),0)=0,"",INDEX('كشف الحساب'!$J$4:$J$203,IFERROR(MATCH(2,'كشف الحساب'!$N$4:$N$203,0),0))),"") | K6: =IFERROR(IF(IFERROR(MATCH(2,'كشف الحساب'!$N$4:$N$203,0),0)=0,"",INDEX('كشف الحساب'!$K$4:$K$203,IFERROR(MATCH(2,'كشف الحساب'!$N$4:$N$203,0),0))),"")
A7: =IFERROR(IF(IFERROR(MATCH(3,'كشف الحساب'!$N$4:$N$203,0),0)=0,"",INDEX('كشف الحساب'!$A$4:$A$203,IFERROR(MATCH(3,'كشف الحساب'!$N$4:$N$203,0),0))),"") | B7: =IFERROR(IF(IFERROR(MATCH(3,'كشف الحساب'!$N$4:$N$203,0),0)=0,"",INDEX('كشف الحساب'!$B$4:$B$203,IFERROR(MATCH(3,'كشف الحساب'!$N$4:$N$203,0),0))),"") | C7: =IFERROR(IF(IFERROR(MATCH(3,'كشف الحساب'!$N$4:$N$203,0),0)=0,"",INDEX('كشف الحساب'!$C$4:$C$203,IFERROR(MATCH(3,'كشف الحساب'!$N$4:$N$203,0),0))),"") | D7: =IFERROR(IF(IFERROR(MATCH(3,'كشف الحساب'!$N$4:$N$203,0),0)=0,"",INDEX('كشف الحساب'!$D$4:$D$203,IFERROR(MATCH(3,'كشف الحساب'!$N$4:$N$203,0),0))),"") | E7: =IFERROR(IF(IFERROR(MATCH(3,'كشف الحساب'!$N$4:$N$203,0),0)=0,"",INDEX('كشف الحساب'!$E$4:$E$203,IFERROR(MATCH(3,'كشف الحساب'!$N$4:$N$203,0),0))),"") | F7: =IFERROR(IF(IFERROR(MATCH(3,'كشف الحساب'!$N$4:$N$203,0),0)=0,"",INDEX('كشف الحساب'!$F$4:$F$203,IFERROR(MATCH(3,'كشف الحساب'!$N$4:$N$203,0),0))),"") | G7: =IFERROR(IF(IFERROR(MATCH(3,'كشف الحساب'!$N$4:$N$203,0),0)=0,"",INDEX('كشف الحساب'!$G$4:$G$203,IFERROR(MATCH(3,'كشف الحساب'!$N$4:$N$203,0),0))),"") | H7: =IFERROR(IF(IFERROR(MATCH(3,'كشف الحساب'!$N$4:$N$203,0),0)=0,"",INDEX('كشف الحساب'!$H$4:$H$203,IFERROR(MATCH(3,'كشف الحساب'!$N$4:$N$203,0),0))),"") | I7: =IFERROR(IF(IFERROR(MATCH(3,'كشف الحساب'!$N$4:$N$203,0),0)=0,"",INDEX('كشف الحساب'!$I$4:$I$203,IFERROR(MATCH(3,'كشف الحساب'!$N$4:$N$203,0),0))),"") | J7: =IFERROR(IF(IFERROR(MATCH(3,'كشف الحساب'!$N$4:$N$203,0),0)=0,"",INDEX('كشف الحساب'!$J$4:$J$203,IFERROR(MATCH(3,'كشف الحساب'!$N$4:$N$203,0),0))),"") | K7: =IFERROR(IF(IFERROR(MATCH(3,'كشف الحساب'!$N$4:$N$203,0),0)=0,"",INDEX('كشف الحساب'!$K$4:$K$203,IFERROR(MATCH(3,'كشف الحساب'!$N$4:$N$203,0),0))),"")
A8: =IFERROR(IF(IFERROR(MATCH(4,'كشف الحساب'!$N$4:$N$203,0),0)=0,"",INDEX('كشف الحساب'!$A$4:$A$203,IFERROR(MATCH(4,'كشف الحساب'!$N$4:$N$203,0),0))),"") | B8: =IFERROR(IF(IFERROR(MATCH(4,'كشف الحساب'!$N$4:$N$203,0),0)=0,"",INDEX('كشف الحساب'!$B$4:$B$203,IFERROR(MATCH(4,'كشف الحساب'!$N$4:$N$203,0),0))),"") | C8: =IFERROR(IF(IFERROR(MATCH(4,'كشف الحساب'!$N$4:$N$203,0),0)=0,"",INDEX('كشف الحساب'!$C$4:$C$203,IFERROR(MATCH(4,'كشف الحساب'!$N$4:$N$203,0),0))),"") | D8: =IFERROR(IF(IFERROR(MATCH(4,'كشف الحساب'!$N$4:$N$203,0),0)=0,"",INDEX('كشف الحساب'!$D$4:$D$203,IFERROR(MATCH(4,'كشف الحساب'!$N$4:$N$203,0),0))),"") | E8: =IFERROR(IF(IFERROR(MATCH(4,'كشف الحساب'!$N$4:$N$203,0),0)=0,"",INDEX('كشف الحساب'!$E$4:$E$203,IFERROR(MATCH(4,'كشف الحساب'!$N$4:$N$203,0),0))),"") | F8: =IFERROR(IF(IFERROR(MATCH(4,'كشف الحساب'!$N$4:$N$203,0),0)=0,"",INDEX('كشف الحساب'!$F$4:$F$203,IFERROR(MATCH(4,'كشف الحساب'!$N$4:$N$203,0),0))),"") | G8: =IFERROR(IF(IFERROR(MATCH(4,'كشف الحساب'!$N$4:$N$203,0),0)=0,"",INDEX('كشف الحساب'!$G$4:$G$203,IFERROR(MATCH(4,'كشف الحساب'!$N$4:$N$203,0),0))),"") | H8: =IFERROR(IF(IFERROR(MATCH(4,'كشف الحساب'!$N$4:$N$203,0),0)=0,"",INDEX('كشف الحساب'!$H$4:$H$203,IFERROR(MATCH(4,'كشف الحساب'!$N$4:$N$203,0),0))),"") | I8: =IFERROR(IF(IFERROR(MATCH(4,'كشف الحساب'!$N$4:$N$203,0),0)=0,"",INDEX('كشف الحساب'!$I$4:$I$203,IFERROR(MATCH(4,'كشف الحساب'!$N$4:$N$203,0),0))),"") | J8: =IFERROR(IF(IFERROR(MATCH(4,'كشف الحساب'!$N$4:$N$203,0),0)=0,"",INDEX('كشف الحساب'!$J$4:$J$203,IFERROR(MATCH(4,'كشف الحساب'!$N$4:$N$203,0),0))),"") | K8: =IFERROR(IF(IFERROR(MATCH(4,'كشف الحساب'!$N$4:$N$203,0),0)=0,"",INDEX('كشف الحساب'!$K$4:$K$203,IFERROR(MATCH(4,'كشف الحساب'!$N$4:$N$203,0),0))),"")
A9: =IFERROR(IF(IFERROR(MATCH(5,'كشف الحساب'!$N$4:$N$203,0),0)=0,"",INDEX('كشف الحساب'!$A$4:$A$203,IFERROR(MATCH(5,'كشف الحساب'!$N$4:$N$203,0),0))),"") | B9: =IFERROR(IF(IFERROR(MATCH(5,'كشف الحساب'!$N$4:$N$203,0),0)=0,"",INDEX('كشف الحساب'!$B$4:$B$203,IFERROR(MATCH(5,'كشف الحساب'!$N$4:$N$203,0),0))),"") | C9: =IFERROR(IF(IFERROR(MATCH(5,'كشف الحساب'!$N$4:$N$203,0),0)=0,"",INDEX('كشف الحساب'!$C$4:$C$203,IFERROR(MATCH(5,'كشف الحساب'!$N$4:$N$203,0),0))),"") | D9: =IFERROR(IF(IFERROR(MATCH(5,'كشف الحساب'!$N$4:$N$203,0),0)=0,"",INDEX('كشف الحساب'!$D$4:$D$203,IFERROR(MATCH(5,'كشف الحساب'!$N$4:$N$203,0),0))),"") | E9: =IFERROR(IF(IFERROR(MATCH(5,'كشف الحساب'!$N$4:$N$203,0),0)=0,"",INDEX('كشف الحساب'!$E$4:$E$203,IFERROR(MATCH(5,'كشف الحساب'!$N$4:$N$203,0),0))),"") | F9: =IFERROR(IF(IFERROR(MATCH(5,'كشف الحساب'!$N$4:$N$203,0),0)=0,"",INDEX('كشف الحساب'!$F$4:$F$203,IFERROR(MATCH(5,'كشف الحساب'!$N$4:$N$203,0),0))),"") | G9: =IFERROR(IF(IFERROR(MATCH(5,'كشف الحساب'!$N$4:$N$203,0),0)=0,"",INDEX('كشف الحساب'!$G$4:$G$203,IFERROR(MATCH(5,'كشف الحساب'!$N$4:$N$203,0),0))),"") | H9: =IFERROR(IF(IFERROR(MATCH(5,'كشف الحساب'!$N$4:$N$203,0),0)=0,"",INDEX('كشف الحساب'!$H$4:$H$203,IFERROR(MATCH(5,'كشف الحساب'!$N$4:$N$203,0),0))),"") | I9: =IFERROR(IF(IFERROR(MATCH(5,'كشف الحساب'!$N$4:$N$203,0),0)=0,"",INDEX('كشف الحساب'!$I$4:$I$203,IFERROR(MATCH(5,'كشف الحساب'!$N$4:$N$203,0),0))),"") | J9: =IFERROR(IF(IFERROR(MATCH(5,'كشف الحساب'!$N$4:$N$203,0),0)=0,"",INDEX('كشف الحساب'!$J$4:$J$203,IFERROR(MATCH(5,'كشف الحساب'!$N$4:$N$203,0),0))),"") | K9: =IFERROR(IF(IFERROR(MATCH(5,'كشف الحساب'!$N$4:$N$203,0),0)=0,"",INDEX('كشف الحساب'!$K$4:$K$203,IFERROR(MATCH(5,'كشف الحساب'!$N$4:$N$203,0),0))),"")
A10: =IFERROR(IF(IFERROR(MATCH(6,'كشف الحساب'!$N$4:$N$203,0),0)=0,"",INDEX('كشف الحساب'!$A$4:$A$203,IFERROR(MATCH(6,'كشف الحساب'!$N$4:$N$203,0),0))),"") | B10: =IFERROR(IF(IFERROR(MATCH(6,'كشف الحساب'!$N$4:$N$203,0),0)=0,"",INDEX('كشف الحساب'!$B$4:$B$203,IFERROR(MATCH(6,'كشف الحساب'!$N$4:$N$203,0),0))),"") | C10: =IFERROR(IF(IFERROR(MATCH(6,'كشف الحساب'!$N$4:$N$203,0),0)=0,"",INDEX('كشف الحساب'!$C$4:$C$203,IFERROR(MATCH(6,'كشف الحساب'!$N$4:$N$203,0),0))),"") | D10: =IFERROR(IF(IFERROR(MATCH(6,'كشف الحساب'!$N$4:$N$203,0),0)=0,"",INDEX('كشف الحساب'!$D$4:$D$203,IFERROR(MATCH(6,'كشف الحساب'!$N$4:$N$203,0),0))),"") | E10: =IFERROR(IF(IFERROR(MATCH(6,'كشف الحساب'!$N$4:$N$203,0),0)=0,"",INDEX('كشف الحساب'!$E$4:$E$203,IFERROR(MATCH(6,'كشف الحساب'!$N$4:$N$203,0),0))),"") | F10: =IFERROR(IF(IFERROR(MATCH(6,'كشف الحساب'!$N$4:$N$203,0),0)=0,"",INDEX('كشف الحساب'!$F$4:$F$203,IFERROR(MATCH(6,'كشف الحساب'!$N$4:$N$203,0),0))),"") | G10: =IFERROR(IF(IFERROR(MATCH(6,'كشف الحساب'!$N$4:$N$203,0),0)=0,"",INDEX('كشف الحساب'!$G$4:$G$203,IFERROR(MATCH(6,'كشف الحساب'!$N$4:$N$203,0),0))),"") | H10: =IFERROR(IF(IFERROR(MATCH(6,'كشف الحساب'!$N$4:$N$203,0),0)=0,"",INDEX('كشف الحساب'!$H$4:$H$203,IFERROR(MATCH(6,'كشف الحساب'!$N$4:$N$203,0),0))),"") | I10: =IFERROR(IF(IFERROR(MATCH(6,'كشف الحساب'!$N$4:$N$203,0),0)=0,"",INDEX('كشف الحساب'!$I$4:$I$203,IFERROR(MATCH(6,'كشف الحساب'!$N$4:$N$203,0),0))),"") | J10: =IFERROR(IF(IFERROR(MATCH(6,'كشف الحساب'!$N$4:$N$203,0),0)=0,"",INDEX('كشف الحساب'!$J$4:$J$203,IFERROR(MATCH(6,'كشف الحساب'!$N$4:$N$203,0),0))),"") | K10: =IFERROR(IF(IFERROR(MATCH(6,'كشف الحساب'!$N$4:$N$203,0),0)=0,"",INDEX('كشف الحساب'!$K$4:$K$203,IFERROR(MATCH(6,'كشف الحساب'!$N$4:$N$203,0),0))),"")
A11: =IFERROR(IF(IFERROR(MATCH(7,'كشف الحساب'!$N$4:$N$203,0),0)=0,"",INDEX('كشف الحساب'!$A$4:$A$203,IFERROR(MATCH(7,'كشف الحساب'!$N$4:$N$203,0),0))),"") | B11: =IFERROR(IF(IFERROR(MATCH(7,'كشف الحساب'!$N$4:$N$203,0),0)=0,"",INDEX('كشف الحساب'!$B$4:$B$203,IFERROR(MATCH(7,'كشف الحساب'!$N$4:$N$203,0),0))),"") | C11: =IFERROR(IF(IFERROR(MATCH(7,'كشف الحساب'!$N$4:$N$203,0),0)=0,"",INDEX('كشف الحساب'!$C$4:$C$203,IFERROR(MATCH(7,'كشف الحساب'!$N$4:$N$203,0),0))),"") | D11: =IFERROR(IF(IFERROR(MATCH(7,'كشف الحساب'!$N$4:$N$203,0),0)=0,"",INDEX('كشف الحساب'!$D$4:$D$203,IFERROR(MATCH(7,'كشف الحساب'!$N$4:$N$203,0),0))),"") | E11: =IFERROR(IF(IFERROR(MATCH(7,'كشف الحساب'!$N$4:$N$203,0),0)=0,"",INDEX('كشف الحساب'!$E$4:$E$203,IFERROR(MATCH(7,'كشف الحساب'!$N$4:$N$203,0),0))),"") | F11: =IFERROR(IF(IFERROR(MATCH(7,'كشف الحساب'!$N$4:$N$203,0),0)=0,"",INDEX('كشف الحساب'!$F$4:$F$203,IFERROR(MATCH(7,'كشف الحساب'!$N$4:$N$203,0),0))),"") | G11: =IFERROR(IF(IFERROR(MATCH(7,'كشف الحساب'!$N$4:$N$203,0),0)=0,"",INDEX('كشف الحساب'!$G$4:$G$203,IFERROR(MATCH(7,'كشف الحساب'!$N$4:$N$203,0),0))),"") | H11: =IFERROR(IF(IFERROR(MATCH(7,'كشف الحساب'!$N$4:$N$203,0),0)=0,"",INDEX('كشف الحساب'!$H$4:$H$203,IFERROR(MATCH(7,'كشف الحساب'!$N$4:$N$203,0),0))),"") | I11: =IFERROR(IF(IFERROR(MATCH(7,'كشف الحساب'!$N$4:$N$203,0),0)=0,"",INDEX('كشف الحساب'!$I$4:$I$203,IFERROR(MATCH(7,'كشف الحساب'!$N$4:$N$203,0),0))),"") | J11: =IFERROR(IF(IFERROR(MATCH(7,'كشف الحساب'!$N$4:$N$203,0),0)=0,"",INDEX('كشف الحساب'!$J$4:$J$203,IFERROR(MATCH(7,'كشف الحساب'!$N$4:$N$203,0),0))),"") | K11: =IFERROR(IF(IFERROR(MATCH(7,'كشف الحساب'!$N$4:$N$203,0),0)=0,"",INDEX('كشف الحساب'!$K$4:$K$203,IFERROR(MATCH(7,'كشف الحساب'!$N$4:$N$203,0),0))),"")
A12: =IFERROR(IF(IFERROR(MATCH(8,'كشف الحساب'!$N$4:$N$203,0),0)=0,"",INDEX('كشف الحساب'!$A$4:$A$203,IFERROR(MATCH(8,'كشف الحساب'!$N$4:$N$203,0),0))),"") | B12: =IFERROR(IF(IFERROR(MATCH(8,'كشف الحساب'!$N$4:$N$203,0),0)=0,"",INDEX('كشف الحساب'!$B$4:$B$203,IFERROR(MATCH(8,'كشف الحساب'!$N$4:$N$203,0),0))),"") | C12: =IFERROR(IF(IFERROR(MATCH(8,'كشف الحساب'!$N$4:$N$203,0),0)=0,"",INDEX('كشف الحساب'!$C$4:$C$203,IFERROR(MATCH(8,'كشف الحساب'!$N$4:$N$203,0),0))),"") | D12: =IFERROR(IF(IFERROR(MATCH(8,'كشف الحساب'!$N$4:$N$203,0),0)=0,"",INDEX('كشف الحساب'!$D$4:$D$203,IFERROR(MATCH(8,'كشف الحساب'!$N$4:$N$203,0),0))),"") | E12: =IFERROR(IF(IFERROR(MATCH(8,'كشف الحساب'!$N$4:$N$203,0),0)=0,"",INDEX('كشف الحساب'!$E$4:$E$203,IFERROR(MATCH(8,'كشف الحساب'!$N$4:$N$203,0),0))),"") | F12: =IFERROR(IF(IFERROR(MATCH(8,'كشف الحساب'!$N$4:$N$203,0),0)=0,"",INDEX('كشف الحساب'!$F$4:$F$203,IFERROR(MATCH(8,'كشف الحساب'!$N$4:$N$203,0),0))),"") | G12: =IFERROR(IF(IFERROR(MATCH(8,'كشف الحساب'!$N$4:$N$203,0),0)=0,"",INDEX('كشف الحساب'!$G$4:$G$203,IFERROR(MATCH(8,'كشف الحساب'!$N$4:$N$203,0),0))),"") | H12: =IFERROR(IF(IFERROR(MATCH(8,'كشف الحساب'!$N$4:$N$203,0),0)=0,"",INDEX('كشف الحساب'!$H$4:$H$203,IFERROR(MATCH(8,'كشف الحساب'!$N$4:$N$203,0),0))),"") | I12: =IFERROR(IF(IFERROR(MATCH(8,'كشف الحساب'!$N$4:$N$203,0),0)=0,"",INDEX('كشف الحساب'!$I$4:$I$203,IFERROR(MATCH(8,'كشف الحساب'!$N$4:$N$203,0),0))),"") | J12: =IFERROR(IF(IFERROR(MATCH(8,'كشف الحساب'!$N$4:$N$203,0),0)=0,"",INDEX('كشف الحساب'!$J$4:$J$203,IFERROR(MATCH(8,'كشف الحساب'!$N$4:$N$203,0),0))),"") | K12: =IFERROR(IF(IFERROR(MATCH(8,'كشف الحساب'!$N$4:$N$203,0),0)=0,"",INDEX('كشف الحساب'!$K$4:$K$203,IFERROR(MATCH(8,'كشف الحساب'!$N$4:$N$203,0),0))),"")
A13: =IFERROR(IF(IFERROR(MATCH(9,'كشف الحساب'!$N$4:$N$203,0),0)=0,"",INDEX('كشف الحساب'!$A$4:$A$203,IFERROR(MATCH(9,'كشف الحساب'!$N$4:$N$203,0),0))),"") | B13: =IFERROR(IF(IFERROR(MATCH(9,'كشف الحساب'!$N$4:$N$203,0),0)=0,"",INDEX('كشف الحساب'!$B$4:$B$203,IFERROR(MATCH(9,'كشف الحساب'!$N$4:$N$203,0),0))),"") | C13: =IFERROR(IF(IFERROR(MATCH(9,'كشف الحساب'!$N$4:$N$203,0),0)=0,"",INDEX('كشف الحساب'!$C$4:$C$203,IFERROR(MATCH(9,'كشف الحساب'!$N$4:$N$203,0),0))),"") | D13: =IFERROR(IF(IFERROR(MATCH(9,'كشف الحساب'!$N$4:$N$203,0),0)=0,"",INDEX('كشف الحساب'!$D$4:$D$203,IFERROR(MATCH(9,'كشف الحساب'!$N$4:$N$203,0),0))),"") | E13: =IFERROR(IF(IFERROR(MATCH(9,'كشف الحساب'!$N$4:$N$203,0),0)=0,"",INDEX('كشف الحساب'!$E$4:$E$203,IFERROR(MATCH(9,'كشف الحساب'!$N$4:$N$203,0),0))),"") | F13: =IFERROR(IF(IFERROR(MATCH(9,'كشف الحساب'!$N$4:$N$203,0),0)=0,"",INDEX('كشف الحساب'!$F$4:$F$203,IFERROR(MATCH(9,'كشف الحساب'!$N$4:$N$203,0),0))),"") | G13: =IFERROR(IF(IFERROR(MATCH(9,'كشف الحساب'!$N$4:$N$203,0),0)=0,"",INDEX('كشف الحساب'!$G$4:$G$203,IFERROR(MATCH(9,'كشف الحساب'!$N$4:$N$203,0),0))),"") | H13: =IFERROR(IF(IFERROR(MATCH(9,'كشف الحساب'!$N$4:$N$203,0),0)=0,"",INDEX('كشف الحساب'!$H$4:$H$203,IFERROR(MATCH(9,'كشف الحساب'!$N$4:$N$203,0),0))),"") | I13: =IFERROR(IF(IFERROR(MATCH(9,'كشف الحساب'!$N$4:$N$203,0),0)=0,"",INDEX('كشف الحساب'!$I$4:$I$203,IFERROR(MATCH(9,'كشف الحساب'!$N$4:$N$203,0),0))),"") | J13: =IFERROR(IF(IFERROR(MATCH(9,'كشف الحساب'!$N$4:$N$203,0),0)=0,"",INDEX('كشف الحساب'!$J$4:$J$203,IFERROR(MATCH(9,'كشف الحساب'!$N$4:$N$203,0),0))),"") | K13: =IFERROR(IF(IFERROR(MATCH(9,'كشف الحساب'!$N$4:$N$203,0),0)=0,"",INDEX('كشف الحساب'!$K$4:$K$203,IFERROR(MATCH(9,'كشف الحساب'!$N$4:$N$203,0),0))),"")
A14: =IFERROR(IF(IFERROR(MATCH(10,'كشف الحساب'!$N$4:$N$203,0),0)=0,"",INDEX('كشف الحساب'!$A$4:$A$203,IFERROR(MATCH(10,'كشف الحساب'!$N$4:$N$203,0),0))),"") | B14: =IFERROR(IF(IFERROR(MATCH(10,'كشف الحساب'!$N$4:$N$203,0),0)=0,"",INDEX('كشف الحساب'!$B$4:$B$203,IFERROR(MATCH(10,'كشف الحساب'!$N$4:$N$203,0),0))),"") | C14: =IFERROR(IF(IFERROR(MATCH(10,'كشف الحساب'!$N$4:$N$203,0),0)=0,"",INDEX('كشف الحساب'!$C$4:$C$203,IFERROR(MATCH(10,'كشف الحساب'!$N$4:$N$203,0),0))),"") | D14: =IFERROR(IF(IFERROR(MATCH(10,'كشف الحساب'!$N$4:$N$203,0),0)=0,"",INDEX('كشف الحساب'!$D$4:$D$203,IFERROR(MATCH(10,'كشف الحساب'!$N$4:$N$203,0),0))),"") | E14: =IFERROR(IF(IFERROR(MATCH(10,'كشف الحساب'!$N$4:$N$203,0),0)=0,"",INDEX('كشف الحساب'!$E$4:$E$203,IFERROR(MATCH(10,'كشف الحساب'!$N$4:$N$203,0),0))),"") | F14: =IFERROR(IF(IFERROR(MATCH(10,'كشف الحساب'!$N$4:$N$203,0),0)=0,"",INDEX('كشف الحساب'!$F$4:$F$203,IFERROR(MATCH(10,'كشف الحساب'!$N$4:$N$203,0),0))),"") | G14: =IFERROR(IF(IFERROR(MATCH(10,'كشف الحساب'!$N$4:$N$203,0),0)=0,"",INDEX('كشف الحساب'!$G$4:$G$203,IFERROR(MATCH(10,'كشف الحساب'!$N$4:$N$203,0),0))),"") | H14: =IFERROR(IF(IFERROR(MATCH(10,'كشف الحساب'!$N$4:$N$203,0),0)=0,"",INDEX('كشف الحساب'!$H$4:$H$203,IFERROR(MATCH(10,'كشف الحساب'!$N$4:$N$203,0),0))),"") | I14: =IFERROR(IF(IFERROR(MATCH(10,'كشف الحساب'!$N$4:$N$203,0),0)=0,"",INDEX('كشف الحساب'!$I$4:$I$203,IFERROR(MATCH(10,'كشف الحساب'!$N$4:$N$203,0),0))),"") | J14: =IFERROR(IF(IFERROR(MATCH(10,'كشف الحساب'!$N$4:$N$203,0),0)=0,"",INDEX('كشف الحساب'!$J$4:$J$203,IFERROR(MATCH(10,'كشف الحساب'!$N$4:$N$203,0),0))),"") | K14: =IFERROR(IF(IFERROR(MATCH(10,'كشف الحساب'!$N$4:$N$203,0),0)=0,"",INDEX('كشف الحساب'!$K$4:$K$203,IFERROR(MATCH(10,'كشف الحساب'!$N$4:$N$203,0),0))),"")
A15: =IFERROR(IF(IFERROR(MATCH(11,'كشف الحساب'!$N$4:$N$203,0),0)=0,"",INDEX('كشف الحساب'!$A$4:$A$203,IFERROR(MATCH(11,'كشف الحساب'!$N$4:$N$203,0),0))),"") | B15: =IFERROR(IF(IFERROR(MATCH(11,'كشف الحساب'!$N$4:$N$203,0),0)=0,"",INDEX('كشف الحساب'!$B$4:$B$203,IFERROR(MATCH(11,'كشف الحساب'!$N$4:$N$203,0),0))),"") | C15: =IFERROR(IF(IFERROR(MATCH(11,'كشف الحساب'!$N$4:$N$203,0),0)=0,"",INDEX('كشف الحساب'!$C$4:$C$203,IFERROR(MATCH(11,'كشف الحساب'!$N$4:$N$203,0),0))),"") | D15: =IFERROR(IF(IFERROR(MATCH(11,'كشف الحساب'!$N$4:$N$203,0),0)=0,"",INDEX('كشف الحساب'!$D$4:$D$203,IFERROR(MATCH(11,'كشف الحساب'!$N$4:$N$203,0),0))),"") | E15: =IFERROR(IF(IFERROR(MATCH(11,'كشف الحساب'!$N$4:$N$203,0),0)=0,"",INDEX('كشف الحساب'!$E$4:$E$203,IFERROR(MATCH(11,'كشف الحساب'!$N$4:$N$203,0),0))),"") | F15: =IFERROR(IF(IFERROR(MATCH(11,'كشف الحساب'!$N$4:$N$203,0),0)=0,"",INDEX('كشف الحساب'!$F$4:$F$203,IFERROR(MATCH(11,'كشف الحساب'!$N$4:$N$203,0),0))),"") | G15: =IFERROR(IF(IFERROR(MATCH(11,'كشف الحساب'!$N$4:$N$203,0),0)=0,"",INDEX('كشف الحساب'!$G$4:$G$203,IFERROR(MATCH(11,'كشف الحساب'!$N$4:$N$203,0),0))),"") | H15: =IFERROR(IF(IFERROR(MATCH(11,'كشف الحساب'!$N$4:$N$203,0),0)=0,"",INDEX('كشف الحساب'!$H$4:$H$203,IFERROR(MATCH(11,'كشف الحساب'!$N$4:$N$203,0),0))),"") | I15: =IFERROR(IF(IFERROR(MATCH(11,'كشف الحساب'!$N$4:$N$203,0),0)=0,"",INDEX('كشف الحساب'!$I$4:$I$203,IFERROR(MATCH(11,'كشف الحساب'!$N$4:$N$203,0),0))),"") | J15: =IFERROR(IF(IFERROR(MATCH(11,'كشف الحساب'!$N$4:$N$203,0),0)=0,"",INDEX('كشف الحساب'!$J$4:$J$203,IFERROR(MATCH(11,'كشف الحساب'!$N$4:$N$203,0),0))),"") | K15: =IFERROR(IF(IFERROR(MATCH(11,'كشف الحساب'!$N$4:$N$203,0),0)=0,"",INDEX('كشف الحساب'!$K$4:$K$203,IFERROR(MATCH(11,'كشف الحساب'!$N$4:$N$203,0),0))),"")
A16: =IFERROR(IF(IFERROR(MATCH(12,'كشف الحساب'!$N$4:$N$203,0),0)=0,"",INDEX('كشف الحساب'!$A$4:$A$203,IFERROR(MATCH(12,'كشف الحساب'!$N$4:$N$203,0),0))),"") | B16: =IFERROR(IF(IFERROR(MATCH(12,'كشف الحساب'!$N$4:$N$203,0),0)=0,"",INDEX('كشف الحساب'!$B$4:$B$203,IFERROR(MATCH(12,'كشف الحساب'!$N$4:$N$203,0),0))),"") | C16: =IFERROR(IF(IFERROR(MATCH(12,'كشف الحساب'!$N$4:$N$203,0),0)=0,"",INDEX('كشف الحساب'!$C$4:$C$203,IFERROR(MATCH(12,'كشف الحساب'!$N$4:$N$203,0),0))),"") | D16: =IFERROR(IF(IFERROR(MATCH(12,'كشف الحساب'!$N$4:$N$203,0),0)=0,"",INDEX('كشف الحساب'!$D$4:$D$203,IFERROR(MATCH(12,'كشف الحساب'!$N$4:$N$203,0),0))),"") | E16: =IFERROR(IF(IFERROR(MATCH(12,'كشف الحساب'!$N$4:$N$203,0),0)=0,"",INDEX('كشف الحساب'!$E$4:$E$203,IFERROR(MATCH(12,'كشف الحساب'!$N$4:$N$203,0),0))),"") | F16: =IFERROR(IF(IFERROR(MATCH(12,'كشف الحساب'!$N$4:$N$203,0),0)=0,"",INDEX('كشف الحساب'!$F$4:$F$203,IFERROR(MATCH(12,'كشف الحساب'!$N$4:$N$203,0),0))),"") | G16: =IFERROR(IF(IFERROR(MATCH(12,'كشف الحساب'!$N$4:$N$203,0),0)=0,"",INDEX('كشف الحساب'!$G$4:$G$203,IFERROR(MATCH(12,'كشف الحساب'!$N$4:$N$203,0),0))),"") | H16: =IFERROR(IF(IFERROR(MATCH(12,'كشف الحساب'!$N$4:$N$203,0),0)=0,"",INDEX('كشف الحساب'!$H$4:$H$203,IFERROR(MATCH(12,'كشف الحساب'!$N$4:$N$203,0),0))),"") | I16: =IFERROR(IF(IFERROR(MATCH(12,'كشف الحساب'!$N$4:$N$203,0),0)=0,"",INDEX('كشف الحساب'!$I$4:$I$203,IFERROR(MATCH(12,'كشف الحساب'!$N$4:$N$203,0),0))),"") | J16: =IFERROR(IF(IFERROR(MATCH(12,'كشف الحساب'!$N$4:$N$203,0),0)=0,"",INDEX('كشف الحساب'!$J$4:$J$203,IFERROR(MATCH(12,'كشف الحساب'!$N$4:$N$203,0),0))),"") | K16: =IFERROR(IF(IFERROR(MATCH(12,'كشف الحساب'!$N$4:$N$203,0),0)=0,"",INDEX('كشف الحساب'!$K$4:$K$203,IFERROR(MATCH(12,'كشف الحساب'!$N$4:$N$203,0),0))),"")
A17: =IFERROR(IF(IFERROR(MATCH(13,'كشف الحساب'!$N$4:$N$203,0),0)=0,"",INDEX('كشف الحساب'!$A$4:$A$203,IFERROR(MATCH(13,'كشف الحساب'!$N$4:$N$203,0),0))),"") | B17: =IFERROR(IF(IFERROR(MATCH(13,'كشف الحساب'!$N$4:$N$203,0),0)=0,"",INDEX('كشف الحساب'!$B$4:$B$203,IFERROR(MATCH(13,'كشف الحساب'!$N$4:$N$203,0),0))),"") | C17: =IFERROR(IF(IFERROR(MATCH(13,'كشف الحساب'!$N$4:$N$203,0),0)=0,"",INDEX('كشف الحساب'!$C$4:$C$203,IFERROR(MATCH(13,'كشف الحساب'!$N$4:$N$203,0),0))),"") | D17: =IFERROR(IF(IFERROR(MATCH(13,'كشف الحساب'!$N$4:$N$203,0),0)=0,"",INDEX('كشف الحساب'!$D$4:$D$203,IFERROR(MATCH(13,'كشف الحساب'!$N$4:$N$203,0),0))),"") | E17: =IFERROR(IF(IFERROR(MATCH(13,'كشف الحساب'!$N$4:$N$203,0),0)=0,"",INDEX('كشف الحساب'!$E$4:$E$203,IFERROR(MATCH(13,'كشف الحساب'!$N$4:$N$203,0),0))),"") | F17: =IFERROR(IF(IFERROR(MATCH(13,'كشف الحساب'!$N$4:$N$203,0),0)=0,"",INDEX('كشف الحساب'!$F$4:$F$203,IFERROR(MATCH(13,'كشف الحساب'!$N$4:$N$203,0),0))),"") | G17: =IFERROR(IF(IFERROR(MATCH(13,'كشف الحساب'!$N$4:$N$203,0),0)=0,"",INDEX('كشف الحساب'!$G$4:$G$203,IFERROR(MATCH(13,'كشف الحساب'!$N$4:$N$203,0),0))),"") | H17: =IFERROR(IF(IFERROR(MATCH(13,'كشف الحساب'!$N$4:$N$203,0),0)=0,"",INDEX('كشف الحساب'!$H$4:$H$203,IFERROR(MATCH(13,'كشف الحساب'!$N$4:$N$203,0),0))),"") | I17: =IFERROR(IF(IFERROR(MATCH(13,'كشف الحساب'!$N$4:$N$203,0),0)=0,"",INDEX('كشف الحساب'!$I$4:$I$203,IFERROR(MATCH(13,'كشف الحساب'!$N$4:$N$203,0),0))),"") | J17: =IFERROR(IF(IFERROR(MATCH(13,'كشف الحساب'!$N$4:$N$203,0),0)=0,"",INDEX('كشف الحساب'!$J$4:$J$203,IFERROR(MATCH(13,'كشف الحساب'!$N$4:$N$203,0),0))),"") | K17: =IFERROR(IF(IFERROR(MATCH(13,'كشف الحساب'!$N$4:$N$203,0),0)=0,"",INDEX('كشف الحساب'!$K$4:$K$203,IFERROR(MATCH(13,'كشف الحساب'!$N$4:$N$203,0),0))),"")
A18: =IFERROR(IF(IFERROR(MATCH(14,'كشف الحساب'!$N$4:$N$203,0),0)=0,"",INDEX('كشف الحساب'!$A$4:$A$203,IFERROR(MATCH(14,'كشف الحساب'!$N$4:$N$203,0),0))),"") | B18: =IFERROR(IF(IFERROR(MATCH(14,'كشف الحساب'!$N$4:$N$203,0),0)=0,"",INDEX('كشف الحساب'!$B$4:$B$203,IFERROR(MATCH(14,'كشف الحساب'!$N$4:$N$203,0),0))),"") | C18: =IFERROR(IF(IFERROR(MATCH(14,'كشف الحساب'!$N$4:$N$203,0),0)=0,"",INDEX('كشف الحساب'!$C$4:$C$203,IFERROR(MATCH(14,'كشف الحساب'!$N$4:$N$203,0),0))),"") | D18: =IFERROR(IF(IFERROR(MATCH(14,'كشف الحساب'!$N$4:$N$203,0),0)=0,"",INDEX('كشف الحساب'!$D$4:$D$203,IFERROR(MATCH(14,'كشف الحساب'!$N$4:$N$203,0),0))),"") | E18: =IFERROR(IF(IFERROR(MATCH(14,'كشف الحساب'!$N$4:$N$203,0),0)=0,"",INDEX('كشف الحساب'!$E$4:$E$203,IFERROR(MATCH(14,'كشف الحساب'!$N$4:$N$203,0),0))),"") | F18: =IFERROR(IF(IFERROR(MATCH(14,'كشف الحساب'!$N$4:$N$203,0),0)=0,"",INDEX('كشف الحساب'!$F$4:$F$203,IFERROR(MATCH(14,'كشف الحساب'!$N$4:$N$203,0),0))),"") | G18: =IFERROR(IF(IFERROR(MATCH(14,'كشف الحساب'!$N$4:$N$203,0),0)=0,"",INDEX('كشف الحساب'!$G$4:$G$203,IFERROR(MATCH(14,'كشف الحساب'!$N$4:$N$203,0),0))),"") | H18: =IFERROR(IF(IFERROR(MATCH(14,'كشف الحساب'!$N$4:$N$203,0),0)=0,"",INDEX('كشف الحساب'!$H$4:$H$203,IFERROR(MATCH(14,'كشف الحساب'!$N$4:$N$203,0),0))),"") | I18: =IFERROR(IF(IFERROR(MATCH(14,'كشف الحساب'!$N$4:$N$203,0),0)=0,"",INDEX('كشف الحساب'!$I$4:$I$203,IFERROR(MATCH(14,'كشف الحساب'!$N$4:$N$203,0),0))),"") | J18: =IFERROR(IF(IFERROR(MATCH(14,'كشف الحساب'!$N$4:$N$203,0),0)=0,"",INDEX('كشف الحساب'!$J$4:$J$203,IFERROR(MATCH(14,'كشف الحساب'!$N$4:$N$203,0),0))),"") | K18: =IFERROR(IF(IFERROR(MATCH(14,'كشف الحساب'!$N$4:$N$203,0),0)=0,"",INDEX('كشف الحساب'!$K$4:$K$203,IFERROR(MATCH(14,'كشف الحساب'!$N$4:$N$203,0),0))),"")
